Workbook

Sheet 商品销售明细表
B1: 2026年商品销售明细表
G2: =SUBTOTAL(9,G4:G4065) -> 3651 | I2: =SUBTOTAL(9,I4:I4065) -> 2494481.5 | K2: =SUBTOTAL(9,K4:K4065) -> 2504870.2
A3: 月份 | B3: 发生日期 | C3: 销售单号 | D3: 编码 | E3: 商品型号 | F3: 客户单位 | G3: 数量 | H3: 单价 | I3: 金额 | J3: 税率 | K3: 含税金额 | L3: 收款分类 | M3: 公司
A4: 1月 | B4: 46027 | C4: 2328/2111 | D4: 2100002016998 | E4: 1500W-4 | F4: EQUIPODONTO ASSISTENCIA TECNICA ODONTOLOGICA LTDA | G4: 2 | H4: 1100 | I4: =G4*H4 -> 2200 | J4: 0.0325 | K4: =ROUND(I4+I4*J4,2) -> 2271.5 | M4: AR
A5: 1月 | B5: 46027 | C5: 2330/2112 | D5: 2100002017018 | E5: COMP 750W 220V | F5: WG ODONTO MANUTENCAO E ASSISTENCIA TECNICA LTDA | G5: 1 | H5: 534.84 | I5: =G5*H5 -> 534.84 | J5: 0.0325 | K5: =ROUND(I5+I5*J5,2) -> 552.22 | M5: AR
A6: 1月 | B6: 46027 | C6: 2332/2113 | D6: 2100002017001 | E6: COMP 550W 110V | F6: FELIPE MARTINIANO ASSUNCAO | G6: 1 | H6: 469.25 | I6: =G6*H6 -> 469.25 | J6: 0.0325 | K6: =ROUND(I6+I6*J6,2) -> 484.5 | M6: AR
A7: 1月 | B7: 46027 | C7: 2335/2114 | D7: 2100002017032 | E7: 1100 8L | F7: VRV FERRAMENTAS | G7: 1 | H7: 661 | I7: =G7*H7 -> 661 | K7: =ROUND(I7+I7*J7,2) -> 661 | M7: AR
A8: 1月 | B8: 46028 | C8: 2337/2116 | D8: 2100002017414 | E8: 配件 | F8: ODONTEK EQUIPAMENTOS ODONTOLOGICOS LTDA | G8: 1 | H8: 450 | I8: =G8*H8 -> 450 | K8: =ROUND(I8+I8*J8,2) -> 450 | M8: AR
A9: 1月 | B9: 46028 | C9: 2337/2116 | D9: 2100002016639 | E9: 配件 | F9: ODONTEK EQUIPAMENTOS ODONTOLOGICOS LTDA | G9: 8 | H9: 15 | I9: =G9*H9 -> 120 | K9: =ROUND(I9+I9*J9,2) -> 120 | M9: AR
A10: 1月 | B10: 46028 | C10: 2329/2117 | D10: 2100002017049 | E10: 1100*2 50L | F10: FERRAGENS HOME HOUSE COM. DE EQUIP. E MAQUINAS LTDA | G10: 1 | H10: 1524 | I10: =G10*H10 -> 1524 | K10: =ROUND(I10+I10*J10,2) -> 1524 | M10: AR
A11: 1月 | B11: 46028 | C11: 2329/2117 | D11: 2100002017469 | E11: BM-1902 25L 127V | F11: FERRAGENS HOME HOUSE COM. DE EQUIP. E MAQUINAS LTDA | G11: 1 | H11: 640 | I11: =G11*H11 -> 640 | K11: =ROUND(I11+I11*J11,2) -> 640 | M11: AR
A12: 1月 | B12: 46028 | C12: 2329/2117 | D12: 2100002016776 | E12: 1200- 8L | F12: FERRAGENS HOME HOUSE COM. DE EQUIP. E MAQUINAS LTDA | G12: 2 | H12: 714.57 | I12: =G12*H12 -> 1429.14 | K12: =ROUND(I12+I12*J12,2) -> 1429.14 | M12: AR
A13: 1月 | B13: 46028 | C13: 2329/2117 | D13: 2100002016752 | E13: 1200 25L | F13: FERRAGENS HOME HOUSE COM. DE EQUIP. E MAQUINAS LTDA | G13: 1 | H13: 902.39 | I13: =G13*H13 -> 902.39 | K13: =ROUND(I13+I13*J13,2) -> 902.39 | M13: AR
A14: 1月 | B14: 46028 | C14: 2343/2119 | D14: 2100002017018 | E14: COMP 750W 220V | F14: THIAGO LOURENCO DO AMARAL | G14: 2 | H14: 603.2 | I14: =G14*H14 -> 1206.4 | K14: =ROUND(I14+I14*J14,2) -> 1206.4 | M14: AR
A15: 1月 | B15: 46028 | C15: 2344/2120 | D15: 2100002017414 | E15: 配件 | F15: JEFERSON ANTONIO PEREIRA ----1100 -220 V | G15: 1 | H15: 400 | I15: =G15*H15 -> 400 | K15: =ROUND(I15+I15*J15,2) -> 400 | M15: AR
A16: 1月 | B16: 46028 | C16: 2334/2121 | D16: 2100002016615 | E16: 1500W-2 | F16: PROTEC COMERCIO E MANUTENCAO DE EQUIPAMENTOS DE SAUDE LTDA | G16: 6 | H16: 639 | I16: =G16*H16 -> 3834 | K16: =ROUND(I16+I16*J16,2) -> 3834 | M16: AR
A17: 1月 | B17: 46028 | C17: 2334/2121 | D17: 2100002016752 | E17: 1200 25L | F17: PROTEC COMERCIO E MANUTENCAO DE EQUIPAMENTOS DE SAUDE LTDA | G17: 1 | H17: 902.39 | I17: =G17*H17 -> 902.39 | K17: =ROUND(I17+I17*J17,2) -> 902.39 | M17: AR
A18: 1月 | B18: 46028 | C18: 2342/2122 | D18: 2100002017018 | E18: COMP 750W 220V | F18: WG ODONTO MANUTENCAO E ASSISTENCIA TECNICA LTDA | G18: 1 | H18: 534.84 | I18: 534.84 | J18: 0.0325 | K18: =ROUND(I18+I18*J18,2) -> 552.22 | M18: AR
A19: 1月 | B19: 46029 | C19: 2345/2123 | D19: 2100002017032 | E19: 1100 8L | F19: PALACIO DAS FERRAMENTAS E PARAFUSOS LTDA | G19: 20 | H19: 659 | I19: =G19*H19 -> 13180 | K19: =ROUND(I19+I19*J19,2) -> 13180 | M19: AR
A20: 1月 | B20: 46029 | C20: 2347/2124 | D20: 2100002016776 | E20: 1200- 8L | F20: FERRAGENS HOME HOUSE COM. DE EQUIP. E MAQUINAS LTDA | G20: 6 | H20: 714.57 | I20: =G20*H20 -> 4287.42 | K20: =ROUND(I20+I20*J20,2) -> 4287.42 | M20: AR
A21: 1月 | B21: 46029 | C21: 2350/2125 | D21: 2100002017490 | E21: 1500W-4 | F21: FRANCISCO NORBERTO DA SILVA | G21: 1 | H21: 1058 | I21: =G21*H21 -> 1058 | K21: =ROUND(I21+I21*J21,2) -> 1058 | M21: AR
A22: 1月 | B22: 46029 | C22: 2341/2126 | D22: 2100002017148 | E22: 1500W-4 | F22: ASSISTECDONTO LTDA | G22: 2 | H22: 1058 | I22: =G22*H22 -> 2116 | J22: 0.0325 | K22: =ROUND(I22+I22*J22,2) -> 2184.77 | M22: AR
A23: 1月 | B23: 46029 | C23: 2341/2126 | D23: 2100002016875 | E23: USK-750W | F23: ASSISTECDONTO LTDA | G23: 4 | H23: 632 | I23: =G23*H23 -> 2528 | J23: 0.0325 | K23: =ROUND(I23+I23*J23,2) -> 2610.16 | M23: AR
A24: 1月 | B24: 46029 | C24: 2341/2126 | D24: 2100002017216 | E24: 配件 | F24: ASSISTECDONTO LTDA | G24: 10 | H24: 20 | I24: =G24*H24 -> 200 | K24: =ROUND(I24+I24*J24,2) -> 200 | M24: AR
A25: 1月 | B25: 46029 | C25: 2341/2126 | D25: 2100002016639 | E25: 配件 | F25: ASSISTECDONTO LTDA | G25: 6 | H25: 60 | I25: =G25*H25 -> 360 | K25: =ROUND(I25+I25*J25,2) -> 360 | M25: AR
A26: 1月 | B26: 46030 | C26: 2352/2127 | D26: 2100002017032 | E26: 1100 8L | F26: VT FERRAMENTAS LTDA | G26: 1 | H26: 665 | I26: =G26*H26 -> 665 | K26: =ROUND(I26+I26*J26,2) -> 665 | M26: AR
A27: 1月 | B27: 46030 | C27: 2349/2128 | D27: 2100002016936 | E27: 1500 50L | F27: MP2 MAQUINAS E FERRAMENTAS LTDA | G27: 1 | H27: 1694 | I27: =G27*H27 -> 1694 | J27: 0.0325 | K27: =ROUND(I27+I27*J27,2) -> 1749.06 | M27: AR
A28: 1月 | B28: 46030 | C28: 2346/2129 | D28: 2100002017483 | E28: 750-25L | F28: GALLARDO COMERCIO DE EQUIPAMENTOS ODONTO MEDICOS LTDA | G28: 5 | H28: 846 | I28: =G28*H28 -> 4230 | K28: =ROUND(I28+I28*J28,2) -> 4230 | M28: AR
A29: 1月 | B29: 46030 | C29: 2346/2129 | D29: 2100002017476 | E29: 550*2-50L | F29: GALLARDO COMERCIO DE EQUIPAMENTOS ODONTO MEDICOS LTDA | G29: 1 | H29: 1685 | I29: =G29*H29 -> 1685 | K29: =ROUND(I29+I29*J29,2) -> 1685 | M29: AR
A30: 1月 | B30: 46030 | C30: 2346/2129 | D30: 2100002017049 | E30: 1100*2 50L | F30: GALLARDO COMERCIO DE EQUIPAMENTOS ODONTO MEDICOS LTDA | G30: 1 | H30: 1524 | I30: =G30*H30 -> 1524 | K30: =ROUND(I30+I30*J30,2) -> 1524 | M30: AR
A31: 1月 | B31: 46030 | C31: 2357/2130 | D31: 2100002017414 | E31: 配件 | F31: CARVALHO MARMORES E GRANITOS LTDA | G31: 2 | H31: 15 | I31: =G31*H31 -> 30 | K31: =ROUND(I31+I31*J31,2) -> 30 | M31: AR
A32: 1月 | B32: 46030 | C32: 2357/2130 | D32: 2100002017414 | E32: 配件 | F32: CARVALHO MARMORES E GRANITOS LTDA | G32: 2 | H32: 40 | I32: =G32*H32 -> 80 | K32: =ROUND(I32+I32*J32,2) -> 80 | M32: AR
A33: 1月 | B33: 46030 | C33: 2357/2130 | D33: 2100002017414 | E33: 配件 | F33: CARVALHO MARMORES E GRANITOS LTDA | G33: 2 | H33: 10 | I33: =G33*H33 -> 20 | K33: =ROUND(I33+I33*J33,2) -> 20 | M33: AR
A34: 1月 | B34: 46030 | C34: 2357/2130 | D34: 2100002017414 | E34: 配件 | F34: CARVALHO MARMORES E GRANITOS LTDA | G34: 1 | H34: 80 | I34: =G34*H34 -> 80 | K34: =ROUND(I34+I34*J34,2) -> 80 | M34: AR
A35: 1月 | B35: 46030 | C35: 2354/2131 | D35: 2100002017483 | E35: 750-25L | F35: FERRAGENS HOME HOUSE COM. DE EQUIP. E MAQUINAS LTDA | G35: 1 | H35: 846 | I35: =G35*H35 -> 846 | K35: =ROUND(I35+I35*J35,2) -> 846 | M35: AR
A36: 1月 | B36: 46030 | C36: 2354/2131 | D36: 2100002017469 | E36: BM-1902 25L 127V | F36: FERRAGENS HOME HOUSE COM. DE EQUIP. E MAQUINAS LTDA | G36: 2 | H36: 640 | I36: =G36*H36 -> 1280 | K36: =ROUND(I36+I36*J36,2) -> 1280 | M36: AR
A37: 1月 | B37: 46030 | C37: 2356/2132 | D37: 2100002016998 | E37: 1500W-4 | F37: KLM LTDA | G37: 1 | H37: 1063.92 | I37: =G37*H37 -> 1063.92 | J37: 0.0325 | K37: =ROUND(I37+I37*J37,2) -> 1098.5 | M37: AR
A38: 1月 | B38: 46030 | C38: 2358/2133 | D38: 2100002017483 | E38: 750-25L | F38: DENTAL TEC COMERCIO E SERVICOS LTDA | G38: 2 | H38: 846 | I38: =G38*H38 -> 1692 | K38: =ROUND(I38+I38*J38,2) -> 1692 | M38: AR
A39: 1月 | B39: 46030 | C39: 2358/2133 | D39: 2100002017476 | E39: 550*2-50L | F39: DENTAL TEC COMERCIO E SERVICOS LTDA | G39: 1 | H39: 1685 | I39: =G39*H39 -> 1685 | K39: =ROUND(I39+I39*J39,2) -> 1685 | M39: AR
A40: 1月 | B40: 46030 | C40: 2338/2134 | D40: 2100002017193 | E40: BM-1902-25L 220V | F40: LOJAO DAS FERRAMENTAS LTDA | G40: 2 | H40: 642 | I40: =G40*H40 -> 1284 | K40: =ROUND(I40+I40*J40,2) -> 1284 | M40: AR
...

Sheet 主营业务收入汇总
A1: 2026年度主营业务收入汇总表 | Q1: 2026年度主营业务收入汇总表
D2: =D6+D7-D8-D9-D10 -> 0.01 | E2: =E6+E7-E8-E9-E10 -> 0 | F2: =F6+F7-F8-F9-F10 -> 0 | G2: =G6+G7-G8-G9-G10 -> 0.02 | H2: =H6+H7-H8-H9-H10 -> -0.01 | I2: =I6+I7-I8-I9-I10 -> -0.01 | J2: =J6+J7-J8-J9-J10 -> 0.01 | K2: =K6+K7-K8-K9-K10 -> 0 | ... P2: =P6+P7-P8-P9-P10 -> -0.01 | Q2: =SUM(J6:J7) -> 0 | AD2: =903577.57-5980 -> 897597.57
A3: 金额单位：元 | Q3: 金额单位：雷亚尔 | R3: 1.289 | S3: 1.3247 | T3: 1.341
A4: 月份 | C4: 科目 | D4: 合计 | E4: 1月 | F4: 2月 | G4: 3月 | H4: 4月 | I4: 5月 | J4: 6月 | K4: 7月 | L4: 8月 | M4: 9月 | N4: 10月 | O4: 11月 | P4: 12月 | Q4: 合计 | R4: 1月 | S4: 2月 | T4: 3月 | U4: 4月 | V4: 5月 | W4: 6月 | X4: 7月 | Y4: 8月 | Z4: 9月 | AA4: 10月 | AB4: 11月 | AC4: 12月
A5: 企业
A6: 总计 | C6: 主营业务收入 | D6: =SUM(E6:P6) -> 3265169.6 | E6: =E11+E16+E21+E26+E31+E36+E41 -> 1776835.5 | F6: =F11+F16+F21+F26+F31+F36+F41 -> 1488334.1 | G6: =G11+G16+G21+G26+G31+G36+G41 -> 0 | H6: =H11+H16+H21+H26+H31+H36+H41 -> 0 | I6: =I11+I16+I21+I26+I31+I36+I41 -> 0 | J6: =J11+J16+J21+J26+J31+J36+J41 -> 0 | K6: =K11+K16+K21+K26+K31+K36+K41 -> 0 | L6: =L11+L16+L21+L26+L31+L36+L41 -> 0 | ... P6: =P11+P16+P21+P26+P31+P36+P41 -> 0 | Q6: =SUM(R6:AC6) -> 2501985.8 | R6: =R11+R16+R21+R26+R31+R36+R41 -> 1378460.4 | S6: =S11+S16+S21+S26+S31+S36+S41 -> 1123525.4 | T6: =T11+T16+T21+T26+T31+T36+T41 -> 0 | U6: =U11+U16+U21+U26+U31+U36+U41 -> 0 | V6: =V11+V16+V21+V26+V31+V36+V41 -> 0 | W6: =W11+W16+W21+W26+W31+W36+W41 -> 0 | X6: =X11+X16+X21+X26+X31+X36+X41 -> 0 | Y6: =Y11+Y16+Y21+Y26+Y31+Y36+Y41 -> 0 | Z6: =Z11+Z16+Z21+Z26+Z31+Z36+Z41 -> 0 | AA6: =AC11+AC16+AC21+AC26+AC31+AC36+AC41 -> 0 | AB6: =AB11+AB16+AB21+AB26+AB31+AB36+AB41 -> 0 | AC6: =AC11+AC16+AC21+AC26+AC31+AC36+AC41 -> 0 | AD6: =S6+S7 -> 1124862.7 | AE6: =F6+F7 -> 1490105.6 | AF6: =Y6+Y7 -> 0
A7: 总计 | C7: 财务费用--刷卡费 | D7: =SUM(E7:P7) -> 3836.84 | E7: =E12+E17+E22+E27+E32+E37+E42 -> 2065.3 | F7: =F12+F17+F22+F27+F32+F37+F42 -> 1771.54 | G7: =G12+G17+G22+G27+G32+G37+G42 -> 0 | H7: =H12+H17+H22+H27+H32+H37+H42 -> 0 | I7: =I12+I17+I22+I27+I32+I37+I42 -> 0 | J7: =J12+J17+J22+J27+J32+J37+J42 -> 0 | K7: =K12+K17+K22+K27+K32+K37+K42 -> 0 | L7: =L12+L17+L22+L27+L32+L37+L42 -> 0 | ... P7: =P12+P17+P22+P27+P32+P37+P42 -> 0 | Q7: =SUM(R7:AC7) -> 2939.5642 | R7: =R12+R17+R22+R27+R32+R37+R42 -> 1602.25 | S7: =S12+S17+S22+S27+S32+S37+S42 -> 1337.3142 | T7: =T12+T17+T22+T27+T32+T37+T42 -> 0 | U7: =U12+U17+U22+U27+U32+U37+U42 -> 0 | V7: =V12+V17+V22+V27+V32+V37+V42 -> 0 | W7: =W12+W17+W22+W27+W32+W37+W42 -> 0 | X7: =X12+X17+X22+X27+X32+X37+X42 -> 0 | Y7: =Y12+Y17+Y22+Y27+Y32+Y37+Y42 -> 0 | Z7: =Z12+Z17+Z22+Z27+Z32+Z37+Z42 -> 0 | AA7: =AC12+AC17+AC22+AC27+AC32+AC37+AC42 -> 0 | AB7: =AB12+AB17+AB22+AB27+AB32+AB37+AB42 -> 0 | AC7: =AC12+AC17+AC22+AC27+AC32+AC37+AC42 -> 0
A8: 总计 | C8: 博莱多收款 | D8: =SUM(E8:P8) -> 1893079.6 | E8: =E13+E18+E23+E28+E33+E38+E43 -> 1016233.3 | F8: =F13+F18+F23+F28+F33+F38+F43 -> 876846.29 | G8: =G13+G18+G23+G28+G33+G38+G43 -> -0.01 | H8: =H13+H18+H23+H28+H33+H38+H43 -> 0 | I8: =I13+I18+I23+I28+I33+I38+I43 -> 0 | J8: =J13+J18+J23+J28+J33+J38+J43 -> 0 | K8: =K13+K18+K23+K28+K33+K38+K43 -> 0 | L8: =L13+L18+L23+L28+L33+L38+L43 -> 0 | ... P8: =P13+P18+P23+P28+P33+P38+P43 -> 0 | Q8: =SUM(R8:AC8) -> 1450309.6 | R8: =R13+R18+R23+R28+R33+R38+R43 -> 788388.94 | S8: =S13+S18+S23+S28+S33+S38+S43 -> 661920.65 | T8: =T13+T18+T23+T28+T33+T38+T43 -> 0 | U8: =U13+U18+U23+U28+U33+U38+U43 -> 0 | V8: =V13+V18+V23+V28+V33+V38+V43 -> 0 | W8: =W13+W18+W23+W28+W33+W38+W43 -> 0 | X8: =X13+X18+X23+X28+X33+X38+X43 -> 0 | Y8: =Y13+Y18+Y23+Y28+Y33+Y38+Y43 -> 0 | Z8: =Z13+Z18+Z23+Z28+Z33+Z38+Z43 -> 0 | AA8: =AC13+AC18+AC23+AC28+AC33+AC38+AC43 -> 0 | AB8: =AB13+AB18+AB23+AB28+AB33+AB38+AB43 -> 0 | AC8: =AC13+AC18+AC23+AC28+AC33+AC38+AC43 -> 0
A9: 总计 | C9: 刷卡收款 | D9: =SUM(E9:P9) -> 313698.19 | E9: =E14+E19+E24+E29+E34+E39+E44 -> 175650.41 | F9: =F14+F19+F24+F29+F34+F39+F44 -> 138047.78 | G9: =G14+G19+G24+G29+G34+G39+G44 -> -0.01 | H9: =H14+H19+H24+H29+H34+H39+H44 -> 0.01 | I9: =I14+I19+I24+I29+I34+I39+I44 -> 0.01 | J9: =J14+J19+J24+J29+J34+J39+J44 -> -0.01 | K9: =K14+K19+K24+K29+K34+K39+K44 -> 0 | L9: =L14+L19+L24+L29+L34+L39+L44 -> -0.01 | ... P9: =P14+P19+P24+P29+P34+P39+P44 -> 0.01 | Q9: =SUM(R9:AC9) -> 240479.33 | R9: =R14+R19+R24+R29+R34+R39+R44 -> 136268.73 | S9: =S14+S19+S24+S29+S34+S39+S44 -> 104210.6 | T9: =T14+T19+T24+T29+T34+T39+T44 -> 0 | U9: =U14+U19+U24+U29+U34+U39+U44 -> 0 | V9: =V14+V19+V24+V29+V34+V39+V44 -> 0 | W9: =W14+W19+W24+W29+W34+W39+W44 -> 0 | X9: =X14+X19+X24+X29+X34+X39+X44 -> 0 | Y9: =Y14+Y19+Y24+Y29+Y34+Y39+Y44 -> 0 | Z9: =Z14+Z19+Z24+Z29+Z34+Z39+Z44 -> 0 | AA9: =AC14+AC19+AC24+AC29+AC34+AC39+AC44 -> 0 | AB9: =AB14+AB19+AB24+AB29+AB34+AB39+AB44 -> 0 | AC9: =AC14+AC19+AC24+AC29+AC34+AC39+AC44 -> 0 | AD9: =S9-S7 -> 102873.29
A10: 总计 | C10: 现款-现金、银行存款 | D10: =SUM(E10:P10) -> 1062228.6 | E10: =E15+E20+E25+E30+E35+E40+E45 -> 587017.07 | F10: =F15+F20+F25+F30+F35+F40+F45 -> 475211.53 | G10: =G15+G20+G25+G30+G35+G40+G45 -> 0 | H10: =H15+H20+H25+H30+H35+H40+H45 -> 0 | I10: =I15+I20+I25+I30+I35+I40+I45 -> 0 | J10: =J15+J20+J25+J30+J35+J40+J45 -> 0 | K10: =K15+K20+K25+K30+K35+K40+K45 -> 0 | L10: =L15+L20+L25+L30+L35+L40+L45 -> 0 | ... P10: =P15+P20+P25+P30+P35+P40+P45 -> 0 | Q10: =SUM(R10:AC10) -> 814136.45 | R10: =R15+R20+R25+R30+R35+R40+R45 -> 455405.02 | S10: =S15+S20+S25+S30+S35+S40+S45 -> 358731.43 | T10: =T15+T20+T25+T30+T35+T40+T45 -> 0 | U10: =U15+U20+U25+U30+U35+U40+U45 -> 0 | V10: =V15+V20+V25+V30+V35+V40+V45 -> 0 | W10: =W15+W20+W25+W30+W35+W40+W45 -> 0 | X10: =X15+X20+X25+X30+X35+X40+X45 -> 0 | Y10: =Y15+Y20+Y25+Y30+Y35+Y40+Y45 -> 0 | Z10: =Z15+Z20+Z25+Z30+Z35+Z40+Z45 -> 0 | AA10: =AC15+AC20+AC25+AC30+AC35+AC40+AC45 -> 0 | AB10: =AB15+AB20+AB25+AB30+AB35+AB40+AB45 -> 0 | AC10: =AC15+AC20+AC25+AC30+AC35+AC40+AC45 -> 0
A11: ARGOTECH | B11: 阿家达 | C11: 主营业务收入 | D11: =SUM(E11:P11) -> 2861588.7 | E11: =ROUND(R11*$R$3,2) -> 1529653.4 | F11: =ROUND(S11*$S$3,2) -> 1331935.3 | G11: =ROUND(T11*$T$3,2) -> 0 | H11: =ROUND(U11*$U$3,2) -> 0 | I11: =ROUND(V11*V$3,2) -> 0 | J11: =ROUND(W11*W$3,2) -> 0 | K11: =ROUND(X11*X$3,2) -> 0 | L11: =ROUND(Y11*Y$3,2) -> 0 | M11: =ROUND(Z11*Z$3,2) -> 0 | N11: =ROUND(AC11*AC$3,2) -> 0 | O11: =ROUND(AB11*AB$3,2) -> 0 | P11: =ROUND(AC11*AC$3,2) -> 0 | Q11: =SUM(R11:AC11) -> 2192159.6 | R11: ='销售帐 -ARGOTECH'!$L390 -> 1186697.8 | S11: ='销售帐 -ARGOTECH'!$L691 -> 1005461.8 | T11: ='销售帐 -ARGOTECH'!$L798 -> 0 | U11: ='销售帐 -ARGOTECH'!$L993 -> 0 | V11: ='销售帐 -ARGOTECH'!$L1286 -> 0 | W11: ='销售帐 -ARGOTECH'!$L1615 -> 0 | X11: ='销售帐 -ARGOTECH'!$L1946 -> 0 | Y11: ='销售帐 -ARGOTECH'!$L2272 -> 0 | Z11: ='销售帐 -ARGOTECH'!$L2641 -> 0 | AA11: ='销售帐 -ARGOTECH'!$L3105 -> 0 | AB11: ='销售帐 -ARGOTECH'!$L3400 -> 0 | AC11: ='销售帐 -ARGOTECH'!$L3508 -> 0 | AD11: =S11+S12 -> 1006603.7 | AE11: =F11+F12 -> 1333447.9 | AF11: =Y11+Y12 -> 0
A12: ARGOTECH | B12: 阿家达 | C12: 财务费用--刷卡费 | D12: =SUM(E12:P12) -> 2991.32 | E12: =ROUND(R12*$R$3,2) -> 1478.74 | F12: =ROUND(S12*$S$3,2) -> 1512.58 | G12: =ROUND(T12*$T$3,2) -> 0 | H12: =ROUND(U12*$U$3,2) -> 0 | I12: =ROUND(V12*V$3,2) -> 0 | J12: =ROUND(W12*W$3,2) -> 0 | K12: =ROUND(X12*X$3,2) -> 0 | L12: =ROUND(Y12*Y$3,2) -> 0 | M12: =ROUND(Z12*Z$3,2) -> 0 | N12: =ROUND(AC12*AC$3,2) -> 0 | O12: =ROUND(AB12*AB$3,2) -> 0 | P12: =ROUND(AC12*AC$3,2) -> 0 | Q12: =SUM(R12:AC12) -> 2289.03 | R12: ='销售帐 -ARGOTECH'!$R390 -> 1147.2 | S12: ='销售帐 -ARGOTECH'!$R691 -> 1141.83 | T12: ='销售帐 -ARGOTECH'!$R798 -> 0 | U12: ='销售帐 -ARGOTECH'!$R993 -> 0 | V12: ='销售帐 -ARGOTECH'!$R1286 -> 0 | W12: ='销售帐 -ARGOTECH'!$R1615 -> 0 | X12: ='销售帐 -ARGOTECH'!$R1946 -> 0 | Y12: ='销售帐 -ARGOTECH'!$R2272 -> 0 | Z12: ='销售帐 -ARGOTECH'!$R2641 -> 0 | AA12: ='销售帐 -ARGOTECH'!$R3105 -> 0 | AB12: ='销售帐 -ARGOTECH'!$R3400 -> 0 | AC12: ='销售帐 -ARGOTECH'!$R3508 -> 0
A13: ARGOTECH | B13: 阿家达 | C13: 博莱多收款 | D13: =SUM(E13:P13) -> 1674833.6 | E13: =ROUND(R13*$R$3,2) -> 892598.28 | F13: =ROUND(S13*$S$3,2) -> 782235.31 | G13: =ROUND(T13*$T$3,2) -> 0 | H13: =ROUND(U13*$U$3,2) -> 0 | I13: =ROUND(V13*V$3,2) -> 0 | J13: =ROUND(W13*W$3,2) -> 0 | K13: =ROUND(X13*X$3,2) -> 0 | L13: =ROUND(Y13*Y$3,2) -> 0 | M13: =ROUND(Z13*Z$3,2) -> 0 | N13: =ROUND(AC13*AC$3,2) -> 0 | O13: =ROUND(AB13*AB$3,2) -> 0 | P13: =ROUND(AC13*AC$3,2) -> 0 | Q13: =SUM(R13:AC13) -> 1282973.4 | R13: ='销售帐 -ARGOTECH'!$O390 -> 692473.45 | S13: ='销售帐 -ARGOTECH'!$O691 -> 590499.97 | T13: ='销售帐 -ARGOTECH'!$O798 -> 0 | U13: ='销售帐 -ARGOTECH'!$O993 -> 0 | V13: ='销售帐 -ARGOTECH'!$O1286 -> 0 | W13: ='销售帐 -ARGOTECH'!$O1615 -> 0 | X13: ='销售帐 -ARGOTECH'!$O1946 -> 0 | Y13: ='销售帐 -ARGOTECH'!$O2272 -> 0 | Z13: ='销售帐 -ARGOTECH'!$O2641 -> 0 | AA13: ='销售帐 -ARGOTECH'!$O3105 -> 0 | AB13: ='销售帐 -ARGOTECH'!$O3400 -> 0 | AC13: ='销售帐 -ARGOTECH'!$O3508 -> 0
A14: ARGOTECH | B14: 阿家达 | C14: 刷卡收款 | D14: =SUM(E14:P14) -> 267979.78 | E14: =ROUND(R14*$R$3,2)+0.01 -> 141204.89 | F14: =ROUND(S14*$S$3,2) -> 126774.85 | G14: =ROUND(T14*$T$3,2)-0.01 -> -0.01 | H14: =ROUND(U14*$U$3,2)+0.01 -> 0.01 | I14: =ROUND(V14*V$3,2)+0.01 -> 0.01 | J14: =ROUND(W14*W$3,2) -> 0 | K14: =ROUND(X14*X$3,2) -> 0 | L14: =ROUND(Y14*Y$3,2)+0.01 -> 0.01 | M14: =ROUND(Z14*Z$3,2) -> 0 | N14: =ROUND(AC14*AC$3,2) -> 0 | O14: =ROUND(AB14*AB$3,2)+0.01 -> 0.01 | P14: =ROUND(AC14*AC$3,2)+0.01 -> 0.01 | Q14: =SUM(R14:AC14) -> 205246.87 | R14: ='销售帐 -ARGOTECH'!$P390 -> 109546.07 | S14: ='销售帐 -ARGOTECH'!$P691 -> 95700.8 | T14: ='销售帐 -ARGOTECH'!$P798 -> 0 | U14: ='销售帐 -ARGOTECH'!$P993 -> 0 | V14: ='销售帐 -ARGOTECH'!$P1286 -> 0 | W14: ='销售帐 -ARGOTECH'!$P1615 -> 0 | X14: ='销售帐 -ARGOTECH'!$P1946 -> 0 | Y14: ='销售帐 -ARGOTECH'!$P2272 -> 0 | Z14: ='销售帐 -ARGOTECH'!$P2641 -> 0 | AA14: ='销售帐 -ARGOTECH'!$P3105 -> 0 | AB14: ='销售帐 -ARGOTECH'!$P3400 -> 0 | AC14: ='销售帐 -ARGOTECH'!$P3508 -> 0 | AD14: =S14-S12 -> 94558.97 | AF14: =R14-R12 -> 108398.87
A15: ARGOTECH | B15: 阿家达 | C15: 现款-现金、银行存款 | D15: =SUM(E15:P15) -> 921766.7 | E15: =ROUND(R15*$R$3,2) -> 497328.99 | F15: =ROUND(S15*$S$3,2) -> 424437.71 | G15: =ROUND(T15*$T$3,2) -> 0 | H15: =ROUND(U15*$U$3,2) -> 0 | I15: =ROUND(V15*V$3,2) -> 0 | J15: =ROUND(W15*W$3,2) -> 0 | K15: =ROUND(X15*X$3,2) -> 0 | L15: =ROUND(Y15*Y$3,2) -> 0 | M15: =ROUND(Z15*Z$3,2) -> 0 | N15: =ROUND(AC15*AC$3,2) -> 0 | O15: =ROUND(AB15*AB$3,2) -> 0 | P15: =ROUND(AC15*AC$3,2) -> 0 | Q15: =SUM(R15:AC15) -> 706228.33 | R15: ='销售帐 -ARGOTECH'!M390+'销售帐 -ARGOTECH'!N390 -> 385825.44 | S15: ='销售帐 -ARGOTECH'!$N691+'销售帐 -ARGOTECH'!M691 -> 320402.89 | T15: ='销售帐 -ARGOTECH'!$N798 -> 0 | U15: ='销售帐 -ARGOTECH'!$N993 -> 0 | V15: ='销售帐 -ARGOTECH'!$N1286 -> 0 | W15: ='销售帐 -ARGOTECH'!$N1615 -> 0 | X15: ='销售帐 -ARGOTECH'!$N1946 -> 0 | Y15: ='销售帐 -ARGOTECH'!$N2272 -> 0 | Z15: ='销售帐 -ARGOTECH'!$N2641 -> 0 | AA15: ='销售帐 -ARGOTECH'!$N3105 -> 0 | AB15: ='销售帐 -ARGOTECH'!$N3400 -> 0 | AC15: ='销售帐 -ARGOTECH'!$N3508 -> 0
A16: CAIYA | B16: 界野 | C16: 主营业务收入 | D16: =SUM(E16:P16) -> 58803.38 | E16: =ROUND(R16*$R$3,2) -> 20735.09 | F16: =ROUND(S16*$S$3,2) -> 38068.29 | G16: =ROUND(T16*$T$3,2) -> 0 | H16: =ROUND(U16*$U$3,2) -> 0 | I16: =ROUND(V16*V$3,2) -> 0 | J16: =ROUND(W16*W$3,2) -> 0 | K16: =ROUND(X16*X$3,2) -> 0 | L16: =ROUND(Y16*Y$3,2) -> 0 | M16: =ROUND(Z16*Z$3,2) -> 0 | N16: =ROUND(AC16*AC$3,2) -> 0 | O16: =ROUND(AB16*AB$3,2) -> 0 | P16: =ROUND(AC16*AC$3,2) -> 0 | Q16: =SUM(R16:AC16) -> 44823.47 | R16: =销售帐CAIYA!L23 -> 16086.18 | S16: =销售帐CAIYA!$L47 -> 28737.29 | T16: =销售帐CAIYA!$L55 -> 0 | U16: =销售帐CAIYA!$L60 -> 0 | V16: =销售帐CAIYA!$L65 -> 0 | W16: =销售帐CAIYA!$L80 -> 0 | X16: =销售帐CAIYA!$L92 -> 0 | Y16: =销售帐CAIYA!$L106 -> 0 | Z16: =销售帐CAIYA!$L116 -> 0 | AA16: =销售帐CAIYA!$L125 -> 0 | AB16: =销售帐CAIYA!$L153 -> 0 | AC16: =销售帐CAIYA!$L161 -> 0 | AD16: =S16+S17 -> 28800.3 | AE16: =F16+F17 -> 38151.76 | AF16: =Y16+Y17 -> 0
A17: CAIYA | B17: 界野 | C17: 财务费用--刷卡费 | D17: =SUM(E17:P17) -> 83.47 | E17: =ROUND(R17*$R$3,2) -> 0 | F17: =ROUND(S17*$S$3,2) -> 83.47 | G17: =ROUND(T17*$T$3,2) -> 0 | H17: =ROUND(U17*$U$3,2) -> 0 | I17: =ROUND(V17*V$3,2) -> 0 | J17: =ROUND(W17*W$3,2) -> 0 | K17: =ROUND(X17*X$3,2) -> 0 | L17: =ROUND(Y17*Y$3,2) -> 0 | M17: =ROUND(Z17*Z$3,2) -> 0 | N17: =ROUND(AC17*AC$3,2) -> 0 | O17: =ROUND(AB17*AB$3,2) -> 0 | P17: =ROUND(AC17*AC$3,2) -> 0 | Q17: =SUM(R17:AC17) -> 63.01 | R17: =销售帐CAIYA!Q23 -> 0 | S17: =销售帐CAIYA!$R47 -> 63.01 | T17: =销售帐CAIYA!$Q55 -> 0 | U17: =销售帐CAIYA!$Q60 -> 0 | V17: =销售帐CAIYA!$Q65 -> 0 | W17: =销售帐CAIYA!$Q80 -> 0 | X17: =销售帐CAIYA!$Q92 -> 0 | Y17: =销售帐CAIYA!$Q106 -> 0 | Z17: =销售帐CAIYA!$Q116 -> 0 | AA17: =销售帐CAIYA!$Q125 -> 0 | AB17: =销售帐CAIYA!$Q153 -> 0 | AC17: =销售帐CAIYA!$Q161 -> 0
A18: CAIYA | B18: 界野 | C18: 博莱多收款 | D18: =SUM(E18:P18) -> 32423.32 | E18: =ROUND(R18*$R$3,2) -> 10455.41 | F18: =ROUND(S18*$S$3,2) -> 21967.92 | G18: =ROUND(T18*$T$3,2)-0.01 -> -0.01 | H18: =ROUND(U18*$U$3,2) -> 0 | I18: =ROUND(V18*V$3,2) -> 0 | J18: =ROUND(W18*W$3,2) -> 0 | K18: =ROUND(X18*X$3,2) -> 0 | L18: =ROUND(Y18*Y$3,2) -> 0 | M18: =ROUND(Z18*Z$3,2) -> 0 | N18: =ROUND(AC18*AC$3,2) -> 0 | O18: =ROUND(AB18*AB$3,2) -> 0 | P18: =ROUND(AC18*AC$3,2) -> 0 | Q18: =SUM(R18:AC18) -> 24694.58 | R18: =销售帐CAIYA!O23 -> 8111.26 | S18: =销售帐CAIYA!$O47 -> 16583.32 | T18: =销售帐CAIYA!$O55 -> 0 | U18: =销售帐CAIYA!$O60 -> 0 | V18: =销售帐CAIYA!$O65 -> 0 | W18: =销售帐CAIYA!$O80 -> 0 | X18: =销售帐CAIYA!$O92 -> 0 | Y18: =销售帐CAIYA!$O106 -> 0 | Z18: =销售帐CAIYA!$O116 -> 0 | AA18: =销售帐CAIYA!$O125 -> 0 | AB18: =销售帐CAIYA!$O153 -> 0 | AC18: =销售帐CAIYA!$O161 -> 0
A19: CAIYA | B19: 界野 | C19: 刷卡收款 | D19: =SUM(E19:P19) -> 3521.85 | E19: =ROUND(R19*$R$3,2) -> 0 | F19: =ROUND(S19*$S$3,2) -> 3521.85 | G19: =ROUND(T19*$T$3,2) -> 0 | H19: =ROUND(U19*$U$3,2) -> 0 | I19: =ROUND(V19*V$3,2) -> 0 | J19: =ROUND(W19*W$3,2) -> 0 | K19: =ROUND(X19*X$3,2) -> 0 | L19: =ROUND(Y19*Y$3,2) -> 0 | M19: =ROUND(Z19*Z$3,2) -> 0 | N19: =ROUND(AC19*AC$3,2) -> 0 | O19: =ROUND(AB19*AB$3,2) -> 0 | P19: =ROUND(AC19*AC$3,2) -> 0 | Q19: =SUM(R19:AC19) -> 2658.6 | R19: =销售帐CAIYA!P23 -> 0 | S19: =销售帐CAIYA!$P47 -> 2658.6 | T19: =销售帐CAIYA!$P55 -> 0 | U19: =销售帐CAIYA!$P60 -> 0 | V19: =销售帐CAIYA!$P65 -> 0 | W19: =销售帐CAIYA!$P80 -> 0 | X19: =销售帐CAIYA!$P92 -> 0 | Y19: =销售帐CAIYA!$P106 -> 0 | Z19: =销售帐CAIYA!$P116 -> 0 | AA19: =销售帐CAIYA!$P125 -> 0 | AB19: =销售帐CAIYA!$P153 -> 0 | AC19: =销售帐CAIYA!$P161 -> 0 | AD19: =S19-S17 -> 2595.59 | AF19: =R19-R17 -> 0
A20: CAIYA | B20: 界野 | C20: 现款-现金、银行存款 | D20: =SUM(E20:P20) -> 22941.67 | E20: =ROUND(R20*$R$3,2)+0.01 -> 10279.68 | F20: =ROUND(S20*$S$3,2) -> 12661.99 | G20: =ROUND(T20*$T$3,2) -> 0 | H20: =ROUND(U20*$U$3,2) -> 0 | I20: =ROUND(V20*V$3,2) -> 0 | J20: =ROUND(W20*W$3,2) -> 0 | K20: =ROUND(X20*X$3,2) -> 0 | L20: =ROUND(Y20*Y$3,2) -> 0 | M20: =ROUND(Z20*Z$3,2) -> 0 | N20: =ROUND(AC20*AC$3,2) -> 0 | O20: =ROUND(AB20*AB$3,2) -> 0 | P20: =ROUND(AC20*AC$3,2) -> 0 | Q20: =SUM(R20:AC20) -> 17533.3 | R20: =销售帐CAIYA!M23+销售帐CAIYA!N23 -> 7974.92 | S20: =销售帐CAIYA!$M55+销售帐CAIYA!$N47 -> 9558.38 | T20: =销售帐CAIYA!$M60+销售帐CAIYA!$N55 -> 0 | U20: =销售帐CAIYA!$M60+销售帐CAIYA!$N60 -> 0 | V20: =销售帐CAIYA!$M65+销售帐CAIYA!$N65 -> 0 | W20: =销售帐CAIYA!$M80+销售帐CAIYA!$N80 -> 0 | X20: =销售帐CAIYA!$M92+销售帐CAIYA!$N92 -> 0 | Y20: =销售帐CAIYA!$M106+销售帐CAIYA!$N106 -> 0 | Z20: =销售帐CAIYA!$M116+销售帐CAIYA!$N116 -> 0 | AA20: =销售帐CAIYA!$M125+销售帐CAIYA!$N125 -> 0 | AB20: =销售帐CAIYA!$M153+销售帐CAIYA!$N153 -> 0 | AC20: =销售帐CAIYA!$M161+销售帐CAIYA!$N161 -> 0
A21: COMPBRASIL | B21: 江帝伯拉ZO | C21: 主营业务收入 | D21: =SUM(E21:P21) -> 0 | E21: =ROUND(R21*$R$3,2) -> 0 | F21: =ROUND(S21*$S$3,2) -> 0 | G21: =ROUND(T21*$T$3,2) -> 0 | H21: =ROUND(U21*$U$3,2) -> 0 | I21: =ROUND(V21*V$3,2) -> 0 | J21: =ROUND(W21*W$3,2) -> 0 | K21: =ROUND(X21*X$3,2) -> 0 | L21: =ROUND(Y21*Y$3,2) -> 0 | M21: =ROUND(Z21*Z$3,2) -> 0 | N21: =ROUND(AC21*AC$3,2) -> 0 | O21: =ROUND(AB21*AB$3,2) -> 0 | P21: =ROUND(AC21*AC$3,2) -> 0 | Q21: =SUM(R21:AC21) -> 0 | R21: ='销售帐 - COMPBRASIL'!$L27 -> 0 | S21: ='销售帐 - COMPBRASIL'!$L35 -> 0 | T21: ='销售帐 - COMPBRASIL'!$L40 -> 0 | U21: ='销售帐 - COMPBRASIL'!$L82 -> 0 | V21: ='销售帐 - COMPBRASIL'!$L270 -> 0 | W21: ='销售帐 - COMPBRASIL'!$L387 -> 0 | X21: ='销售帐 - COMPBRASIL'!$L479 -> 0 | Y21: ='销售帐 - COMPBRASIL'!$L578 -> 0 | Z21: ='销售帐 - COMPBRASIL'!$L645 -> 0 | AA21: ='销售帐 - COMPBRASIL'!$L733 -> 0 | AB21: ='销售帐 - COMPBRASIL'!$L798 -> 0 | AC21: ='销售帐 - COMPBRASIL'!$L809 -> 0 | AE21: =E21+E22 -> 0 | AF21: =Y21+Y22 -> 0
A22: COMPBRASIL | B22: 江帝伯拉ZO | C22: 财务费用--刷卡费 | D22: =SUM(E22:P22) -> 0 | E22: =ROUND(R22*$R$3,2) -> 0 | F22: =ROUND(S22*$S$3,2) -> 0 | G22: =ROUND(T22*$T$3,2) -> 0 | H22: =ROUND(U22*$U$3,2) -> 0 | I22: =ROUND(V22*V$3,2) -> 0 | J22: =ROUND(W22*W$3,2) -> 0 | K22: =ROUND(X22*X$3,2) -> 0 | L22: =ROUND(Y22*Y$3,2) -> 0 | M22: =ROUND(Z22*Z$3,2) -> 0 | N22: =ROUND(AC22*AC$3,2) -> 0 | O22: =ROUND(AB22*AB$3,2) -> 0 | P22: =ROUND(AC22*AC$3,2) -> 0 | Q22: =SUM(R22:AC22) -> 0 | R22: ='销售帐 - COMPBRASIL'!$Q27 -> 0 | S22: ='销售帐 - COMPBRASIL'!$Q35 -> 0 | T22: ='销售帐 - COMPBRASIL'!$Q40 -> 0 | U22: ='销售帐 - COMPBRASIL'!$Q82 -> 0 | V22: ='销售帐 - COMPBRASIL'!$Q270 -> 0 | W22: ='销售帐 - COMPBRASIL'!$Q387 -> 0 | X22: ='销售帐 - COMPBRASIL'!$Q479 -> 0 | Y22: ='销售帐 - COMPBRASIL'!$Q578 -> 0 | Z22: ='销售帐 - COMPBRASIL'!$Q645 -> 0 | AA22: ='销售帐 - COMPBRASIL'!$Q733 -> 0 | AB22: ='销售帐 - COMPBRASIL'!$Q798 -> 0 | AC22: ='销售帐 - COMPBRASIL'!$Q809 -> 0
A23: COMPBRASIL | B23: 江帝伯拉ZO | C23: 博莱多收款 | D23: =SUM(E23:P23) -> 0.01 | E23: =ROUND(R23*$R$3,2) -> 0 | F23: =ROUND(S23*$S$3,2)+0.01 -> 0.01 | G23: =ROUND(T23*$T$3,2) -> 0 | H23: =ROUND(U23*$U$3,2) -> 0 | I23: =ROUND(V23*V$3,2) -> 0 | J23: =ROUND(W23*W$3,2) -> 0 | K23: =ROUND(X23*X$3,2) -> 0 | L23: =ROUND(Y23*Y$3,2) -> 0 | M23: =ROUND(Z23*Z$3,2) -> 0 | N23: =ROUND(AC23*AC$3,2) -> 0 | O23: =ROUND(AB23*AB$3,2) -> 0 | P23: =ROUND(AC23*AC$3,2) -> 0 | Q23: =SUM(R23:AC23) -> 0 | R23: ='销售帐 - COMPBRASIL'!$O27 -> 0 | S23: ='销售帐 - COMPBRASIL'!$O35 -> 0 | T23: ='销售帐 - COMPBRASIL'!$O40 -> 0 | U23: ='销售帐 - COMPBRASIL'!$O82 -> 0 | V23: ='销售帐 - COMPBRASIL'!$O270 -> 0 | W23: ='销售帐 - COMPBRASIL'!$O387 -> 0 | X23: ='销售帐 - COMPBRASIL'!$O479 -> 0 | Y23: ='销售帐 - COMPBRASIL'!$O578 -> 0 | Z23: ='销售帐 - COMPBRASIL'!$O645 -> 0 | AA23: ='销售帐 - COMPBRASIL'!$O733 -> 0 | AB23: ='销售帐 - COMPBRASIL'!$O798 -> 0 | AC23: ='销售帐 - COMPBRASIL'!$O809 -> 0
A24: COMPBRASIL | B24: 江帝伯拉ZO | C24: 刷卡收款 | D24: =SUM(E24:P24) -> 0 | E24: =ROUND(R24*$R$3,2) -> 0 | F24: =ROUND(S24*$S$3,2) -> 0 | G24: =ROUND(T24*$T$3,2) -> 0 | H24: =ROUND(U24*$U$3,2) -> 0 | I24: =ROUND(V24*V$3,2) -> 0 | J24: =ROUND(W24*W$3,2) -> 0 | K24: =ROUND(X24*X$3,2) -> 0 | L24: =ROUND(Y24*Y$3,2) -> 0 | M24: =ROUND(Z24*Z$3,2) -> 0 | N24: =ROUND(AC24*AC$3,2) -> 0 | O24: =ROUND(AB24*AB$3,2) -> 0 | P24: =ROUND(AC24*AC$3,2) -> 0 | Q24: =SUM(R24:AC24) -> 0 | R24: ='销售帐 - COMPBRASIL'!$P27 -> 0 | S24: ='销售帐 - COMPBRASIL'!$P35 -> 0 | T24: ='销售帐 - COMPBRASIL'!$P40 -> 0 | U24: ='销售帐 - COMPBRASIL'!$P82 -> 0 | V24: ='销售帐 - COMPBRASIL'!$P270 -> 0 | W24: ='销售帐 - COMPBRASIL'!$P387 -> 0 | X24: ='销售帐 - COMPBRASIL'!$P479 -> 0 | Y24: ='销售帐 - COMPBRASIL'!$P578 -> 0 | Z24: ='销售帐 - COMPBRASIL'!$P645 -> 0 | AA24: ='销售帐 - COMPBRASIL'!$P733 -> 0 | AB24: ='销售帐 - COMPBRASIL'!$P798 -> 0 | AC24: ='销售帐 - COMPBRASIL'!$P809 -> 0 | AD24: =R24-R22 -> 0
A25: COMPBRASIL | B25: 江帝伯拉ZO | C25: 现款-现金、银行存款 | D25: =SUM(E25:P25) -> 0 | E25: =ROUND(R25*$R$3,2) -> 0 | F25: =ROUND(S25*$S$3,2) -> 0 | G25: =ROUND(T25*$T$3,2) -> 0 | H25: =ROUND(U25*$U$3,2) -> 0 | I25: =ROUND(V25*V$3,2) -> 0 | J25: =ROUND(W25*W$3,2) -> 0 | K25: =ROUND(X25*X$3,2) -> 0 | L25: =ROUND(Y25*Y$3,2) -> 0 | M25: =ROUND(Z25*Z$3,2) -> 0 | N25: =ROUND(AC25*AC$3,2) -> 0 | O25: =ROUND(AB25*AB$3,2) -> 0 | P25: =ROUND(AC25*AC$3,2) -> 0 | Q25: =SUM(R25:AC25) -> 0 | R25: ='销售帐 - COMPBRASIL'!$M27+'销售帐 - COMPBRASIL'!$N27 -> 0 | S25: ='销售帐 - COMPBRASIL'!$M35+'销售帐 - COMPBRASIL'!$N35 -> 0 | T25: ='销售帐 - COMPBRASIL'!$M40+'销售帐 - COMPBRASIL'!$N40 -> 0 | U25: ='销售帐 - COMPBRASIL'!$M82+'销售帐 - COMPBRASIL'!$N82 -> 0 | V25: ='销售帐 - COMPBRASIL'!$M270+'销售帐 - COMPBRASIL'!$N270 -> 0 | W25: ='销售帐 - COMPBRASIL'!$M387+'销售帐 - COMPBRASIL'!$N387 -> 0 | X25: ='销售帐 - COMPBRASIL'!$M479+'销售帐 - COMPBRASIL'!$N479 -> 0 | Y25: ='销售帐 - COMPBRASIL'!$M578+'销售帐 - COMPBRASIL'!$N578 -> 0 | Z25: ='销售帐 - COMPBRASIL'!$M645+'销售帐 - COMPBRASIL'!$N645 -> 0 | AA25: ='销售帐 - COMPBRASIL'!$M733+'销售帐 - COMPBRASIL'!$N733 -> 0 | AB25: ='销售帐 - COMPBRASIL'!$M798+'销售帐 - COMPBRASIL'!$N798 -> 0 | AC25: ='销售帐 - COMPBRASIL'!$M809+'销售帐 - COMPBRASIL'!$N809 -> 0
A26: DEYUN | B26: 德永 | C26: 主营业务收入 | D26: =SUM(E26:P26) -> 13025.99 | E26: =ROUND(R26*$R$3,2) -> 13025.99 | F26: =ROUND(S26*$S$3,2) -> 0 | G26: =ROUND(T26*$T$3,2) -> 0 | H26: =ROUND(U26*$U$3,2) -> 0 | I26: =ROUND(V26*V$3,2) -> 0 | J26: =ROUND(W26*W$3,2) -> 0 | K26: =ROUND(X26*X$3,2) -> 0 | L26: =ROUND(Y26*Y$3,2) -> 0 | M26: =ROUND(Z26*Z$3,2) -> 0 | N26: =ROUND(AC26*AC$3,2) -> 0 | O26: =ROUND(AB26*AB$3,2) -> 0 | P26: =ROUND(AC26*AC$3,2) -> 0 | Q26: =SUM(R26:AC26) -> 10105.5 | R26: =销售帐DEYUN!$L13 -> 10105.5 | S26: =销售帐DEYUN!$L17 -> 0 | T26: =销售帐DEYUN!L23 -> 0 | V26: =销售帐DEYUN!$L32 -> 0 | W26: =销售帐DEYUN!$L37 -> 0 | X26: =销售帐DEYUN!$L48 -> 0 | Y26: =销售帐DEYUN!$L61 -> 0 | Z26: =销售帐DEYUN!$L74 -> 0 | AA26: =销售帐DEYUN!$L86 -> 0 | AB26: =销售帐DEYUN!$L96 -> 0 | AC26: =销售帐DEYUN!$L107 -> 0 | AD26: =S26+S27 -> 0 | AE26: =F26+F27 -> 0 | AF26: =Y26+Y27 -> 0
A27: DEYUN | B27: 德永 | C27: 财务费用--刷卡费 | D27: =SUM(E27:P27) -> 0 | E27: =ROUND(R27*$R$3,2) -> 0 | F27: =ROUND(S27*$S$3,2) -> 0 | G27: =ROUND(T27*$T$3,2) -> 0 | H27: =ROUND(U27*$U$3,2) -> 0 | I27: =ROUND(V27*V$3,2) -> 0 | J27: =ROUND(W27*W$3,2) -> 0 | K27: =ROUND(X27*X$3,2) -> 0 | L27: =ROUND(Y27*Y$3,2) -> 0 | M27: =ROUND(Z27*Z$3,2) -> 0 | N27: =ROUND(AC27*AC$3,2) -> 0 | O27: =ROUND(AB27*AB$3,2) -> 0 | P27: =ROUND(AC27*AC$3,2) -> 0 | Q27: =SUM(R27:AC27) -> 0 | R27: =销售帐DEYUN!$Q13 -> 0 | S27: =销售帐DEYUN!$Q17 -> 0 | T27: =销售帐DEYUN!Q23 -> 0 | V27: =销售帐DEYUN!$Q32 -> 0 | W27: =销售帐DEYUN!$Q37 -> 0 | X27: =销售帐DEYUN!$Q48 -> 0 | Y27: =销售帐DEYUN!$Q61 -> 0 | Z27: =销售帐DEYUN!$Q74 -> 0 | AA27: =销售帐DEYUN!$Q86 -> 0 | AB27: =销售帐DEYUN!$Q96 -> 0 | AC27: =销售帐DEYUN!$Q107 -> 0
A28: DEYUN | B28: 德永 | C28: 博莱多收款 | D28: =SUM(E28:P28) -> 13025.99 | E28: =ROUND(R28*$R$3,2) -> 13025.99 | F28: =ROUND(S28*$S$3,2) -> 0 | G28: =ROUND(T28*$T$3,2) -> 0 | H28: =ROUND(U28*$U$3,2) -> 0 | I28: =ROUND(V28*V$3,2) -> 0 | J28: =ROUND(W28*W$3,2) -> 0 | K28: =ROUND(X28*X$3,2) -> 0 | L28: =ROUND(Y28*Y$3,2) -> 0 | M28: =ROUND(Z28*Z$3,2) -> 0 | N28: =ROUND(AC28*AC$3,2) -> 0 | O28: =ROUND(AB28*AB$3,2) -> 0 | P28: =ROUND(AC28*AC$3,2) -> 0 | Q28: =SUM(R28:AC28) -> 10105.5 | R28: =销售帐DEYUN!$O13 -> 10105.5 | S28: =销售帐DEYUN!$O17 -> 0 | T28: =销售帐DEYUN!O23 -> 0 | V28: =销售帐DEYUN!$O32 -> 0 | W28: =销售帐DEYUN!$O37 -> 0 | X28: =销售帐DEYUN!$O48 -> 0 | Y28: =销售帐DEYUN!$O61 -> 0 | Z28: =销售帐DEYUN!$O74 -> 0 | AA28: =销售帐DEYUN!$O86 -> 0 | AB28: =销售帐DEYUN!$O96 -> 0 | AC28: =销售帐DEYUN!$O107 -> 0
A29: DEYUN | B29: 德永 | C29: 刷卡收款 | D29: =SUM(E29:P29) -> -0.01 | E29: =ROUND(R29*$R$3,2) -> 0 | F29: =ROUND(S29*$S$3,2) -> 0 | G29: =ROUND(T29*$T$3,2) -> 0 | H29: =ROUND(U29*$U$3,2) -> 0 | I29: =ROUND(V29*V$3,2) -> 0 | J29: =ROUND(W29*W$3,2) -> 0 | K29: =ROUND(X29*X$3,2) -> 0 | L29: =ROUND(Y29*Y$3,2)-0.01 -> -0.01 | M29: =ROUND(Z29*Z$3,2) -> 0 | N29: =ROUND(AC29*AC$3,2) -> 0 | O29: =ROUND(AB29*AB$3,2) -> 0 | P29: =ROUND(AC29*AC$3,2) -> 0 | Q29: =SUM(R29:AC29) -> 0 | R29: =销售帐DEYUN!$P13 -> 0 | S29: =销售帐DEYUN!$P17 -> 0 | T29: =销售帐DEYUN!P23 -> 0 | V29: =销售帐DEYUN!$P32 -> 0 | W29: =销售帐DEYUN!$P37 -> 0 | X29: =销售帐DEYUN!$P48 -> 0 | Y29: =销售帐DEYUN!$P61 -> 0 | Z29: =销售帐DEYUN!$P74 -> 0 | AA29: =销售帐DEYUN!$P86 -> 0 | AB29: =销售帐DEYUN!$P96 -> 0 | AC29: =销售帐DEYUN!$P107 -> 0 | AD29: =S29-S27 -> 0 | AF29: =R29-R27 -> 0
A30: DEYUN | B30: 德永 | C30: 现款-现金、银行存款 | D30: =SUM(E30:P30) -> 0 | E30: =ROUND(R30*$R$3,2) -> 0 | F30: =ROUND(S30*$S$3,2) -> 0 | G30: =ROUND(T30*$T$3,2) -> 0 | H30: =ROUND(U30*$U$3,2) -> 0 | I30: =ROUND(V30*V$3,2) -> 0 | J30: =ROUND(W30*W$3,2) -> 0 | K30: =ROUND(X30*X$3,2) -> 0 | L30: =ROUND(Y30*Y$3,2) -> 0 | M30: =ROUND(Z30*Z$3,2) -> 0 | N30: =ROUND(AC30*AC$3,2) -> 0 | O30: =ROUND(AB30*AB$3,2) -> 0 | P30: =ROUND(AC30*AC$3,2) -> 0 | Q30: =SUM(R30:AC30) -> 0 | R30: =销售帐DEYUN!$M13+销售帐DEYUN!$N13 -> 0 | S30: =销售帐DEYUN!$M17+销售帐DEYUN!$N17 -> 0 | T30: =销售帐DEYUN!M23+销售帐DEYUN!N23 -> 0 | V30: =销售帐DEYUN!$M32+销售帐DEYUN!$N32 -> 0 | W30: =销售帐DEYUN!$M37+销售帐DEYUN!$N37 -> 0 | X30: =销售帐DEYUN!$M48+销售帐DEYUN!$N48 -> 0 | Y30: =销售帐DEYUN!$M61+销售帐DEYUN!$N61 -> 0 | Z30: =销售帐DEYUN!$M74+销售帐DEYUN!$N74 -> 0 | AA30: =销售帐DEYUN!$M86+销售帐DEYUN!$N86 -> 0 | AB30: =销售帐DEYUN!$M96+销售帐DEYUN!$N96 -> 0 | AC30: =销售帐DEYUN!$M107+销售帐DEYUN!$N107 -> 0
A31: MARTELUX | B31: 麻德罗思 | C31: 主营业务收入 | D31: =SUM(E31:P31) -> 281344.77 | E31: =ROUND(R31*$R$3,2) -> 163676.64 | F31: =ROUND(S31*$S$3,2) -> 117668.13 | G31: =ROUND(T31*$T$3,2) -> 0 | H31: =ROUND(U31*$U$3,2) -> 0 | I31: =ROUND(V31*V$3,2) -> 0 | J31: =ROUND(W31*W$3,2) -> 0 | K31: =ROUND(X31*X$3,2) -> 0 | L31: =ROUND(Y31*Y$3,2) -> 0 | M31: =ROUND(Z31*Z$3,2) -> 0 | N31: =ROUND(AC31*AC$3,2) -> 0 | O31: =ROUND(AB31*AB$3,2) -> 0 | P31: =ROUND(AC31*AC$3,2) -> 0 | Q31: =SUM(R31:AC31) -> 215805.8 | R31: ='销售帐 MARTELUX'!$L100 -> 126979.55 | S31: ='销售帐 MARTELUX'!$L172 -> 88826.246 | T31: ='销售帐 MARTELUX'!L335 -> 0 | U31: ='销售帐 MARTELUX'!$L446 -> 0 | V31: ='销售帐 MARTELUX'!$L610 -> 0 | W31: ='销售帐 MARTELUX'!$L839 -> 0 | X31: ='销售帐 MARTELUX'!$L1080 -> 0 | Y31: ='销售帐 MARTELUX'!$L1351 -> 0 | Z31: ='销售帐 MARTELUX'!$L1557 -> 0 | AA31: ='销售帐 MARTELUX'!$L1742 -> 0 | AB31: ='销售帐 MARTELUX'!$L1895 -> 0 | AC31: ='销售帐 MARTELUX'!$L1929 -> 0 | AD31: =S31+S32 -> 88958.72 | AE31: =F31+F32 -> 117843.62 | AF31: =Y31+Y32 -> 0
A32: MARTELUX | B32: 麻德罗思 | C32: 财务费用--刷卡费 | D32: =SUM(E32:P32) -> 596.34 | E32: =ROUND(R32*$R$3,2) -> 420.85 | F32: =ROUND(S32*$S$3,2) -> 175.49 | G32: =ROUND(T32*$T$3,2) -> 0 | H32: =ROUND(U32*$U$3,2) -> 0 | I32: =ROUND(V32*V$3,2) -> 0 | J32: =ROUND(W32*W$3,2) -> 0 | K32: =ROUND(X32*X$3,2) -> 0 | L32: =ROUND(Y32*Y$3,2) -> 0 | M32: =ROUND(Z32*Z$3,2) -> 0 | N32: =ROUND(AC32*AC$3,2) -> 0 | O32: =ROUND(AB32*AB$3,2) -> 0 | P32: =ROUND(AC32*AC$3,2) -> 0 | Q32: =SUM(R32:AC32) -> 458.96424 | R32: ='销售帐 MARTELUX'!$R100 -> 326.49 | S32: ='销售帐 MARTELUX'!$R172 -> 132.47424 | T32: ='销售帐 MARTELUX'!R335 -> 0 | U32: ='销售帐 MARTELUX'!$R446 -> 0 | V32: ='销售帐 MARTELUX'!$R610 -> 0 | W32: ='销售帐 MARTELUX'!$R839 -> 0 | X32: ='销售帐 MARTELUX'!$R1080 -> 0 | Y32: ='销售帐 MARTELUX'!$R1351 -> 0 | Z32: ='销售帐 MARTELUX'!$R1557 -> 0 | AA32: ='销售帐 MARTELUX'!$R1742 -> 0 | AB32: ='销售帐 MARTELUX'!$R1895 -> 0 | AC32: ='销售帐 MARTELUX'!$R1929 -> 0
A33: MARTELUX | B33: 麻德罗思 | C33: 博莱多收款 | D33: =SUM(E33:P33) -> 151631.33 | E33: =ROUND(R33*$R$3,2) -> 78988.28 | F33: =ROUND(S33*$S$3,2) -> 72643.05 | G33: =ROUND(T33*$T$3,2) -> 0 | H33: =ROUND(U33*$U$3,2) -> 0 | I33: =ROUND(V33*V$3,2) -> 0 | J33: =ROUND(W33*W$3,2) -> 0 | K33: =ROUND(X33*X$3,2) -> 0 | L33: =ROUND(Y33*Y$3,2) -> 0 | M33: =ROUND(Z33*Z$3,2) -> 0 | N33: =ROUND(AC33*AC$3,2) -> 0 | O33: =ROUND(AB33*AB$3,2) -> 0 | P33: =ROUND(AC33*AC$3,2) -> 0 | Q33: =SUM(R33:AC33) -> 116116.09 | R33: ='销售帐 MARTELUX'!$O100 -> 61278.73 | S33: ='销售帐 MARTELUX'!$O172 -> 54837.36 | T33: ='销售帐 MARTELUX'!O335 -> 0 | U33: ='销售帐 MARTELUX'!$O446 -> 0 | V33: ='销售帐 MARTELUX'!$O610 -> 0 | W33: ='销售帐 MARTELUX'!$O839 -> 0 | X33: ='销售帐 MARTELUX'!$O1080 -> 0 | Y33: ='销售帐 MARTELUX'!$O1351 -> 0 | Z33: ='销售帐 MARTELUX'!$O1557 -> 0 | AA33: ='销售帐 MARTELUX'!$O1742 -> 0 | AB33: ='销售帐 MARTELUX'!$O1895 -> 0 | AC33: ='销售帐 MARTELUX'!$O1929 -> 0
A34: MARTELUX | B34: 麻德罗思 | C34: 刷卡收款 | D34: =SUM(E34:P34) -> 34113.07 | E34: =ROUND(R34*$R$3,2) -> 26362.02 | F34: =ROUND(S34*$S$3,2) -> 7751.08 | G34: =ROUND(T34*$T$3,2) -> 0 | H34: =ROUND(U34*$U$3,2) -> 0 | I34: =ROUND(V34*V$3,2) -> 0 | J34: =ROUND(W34*W$3,2)-0.01 -> -0.01 | K34: =ROUND(X34*X$3,2) -> 0 | L34: =ROUND(Y34*Y$3,2)-0.01 -> -0.01 | M34: =ROUND(Z34*Z$3,2) -> 0 | N34: =ROUND(AC34*AC$3,2)-0.01 -> -0.01 | O34: =ROUND(AB34*AB$3,2) -> 0 | P34: =ROUND(AC34*AC$3,2) -> 0 | Q34: =SUM(R34:AC34) -> 26302.73 | R34: ='销售帐 MARTELUX'!$P100 -> 20451.53 | S34: ='销售帐 MARTELUX'!$P172 -> 5851.2 | T34: ='销售帐 MARTELUX'!P335 -> 0 | U34: ='销售帐 MARTELUX'!$P446 -> 0 | V34: ='销售帐 MARTELUX'!$P610 -> 0 | W34: ='销售帐 MARTELUX'!$P839 -> 0 | X34: ='销售帐 MARTELUX'!$P1080 -> 0 | Y34: ='销售帐 MARTELUX'!$P1351 -> 0 | Z34: ='销售帐 MARTELUX'!$P1557 -> 0 | AA34: ='销售帐 MARTELUX'!$P1742 -> 0 | AB34: ='销售帐 MARTELUX'!$P1895 -> 0 | AC34: ='销售帐 MARTELUX'!$P1929 -> 0 | AD34: =S34-S32 -> 5718.7258 | AF34: =R34-R32 -> 20125.04
A35: MARTELUX | B35: 麻德罗思 | C35: 现款-现金、银行存款 | D35: =SUM(E35:P35) -> 96196.66 | E35: =ROUND(R35*$R$3,2) -> 58747.18 | F35: =ROUND(S35*$S$3,2) -> 37449.48 | G35: =ROUND(T35*$T$3,2) -> 0 | H35: =ROUND(U35*$U$3,2) -> 0 | I35: =ROUND(V35*V$3,2) -> 0 | J35: =ROUND(W35*W$3,2) -> 0 | K35: =ROUND(X35*X$3,2) -> 0 | L35: =ROUND(Y35*Y$3,2) -> 0 | M35: =ROUND(Z35*Z$3,2) -> 0 | N35: =ROUND(AC35*AC$3,2) -> 0 | O35: =ROUND(AB35*AB$3,2) -> 0 | P35: =ROUND(AC35*AC$3,2) -> 0 | Q35: =SUM(R35:AC35) -> 73845.94 | R35: ='销售帐 MARTELUX'!$M100+'销售帐 MARTELUX'!$N100 -> 45575.78 | S35: ='销售帐 MARTELUX'!$M172+'销售帐 MARTELUX'!$N172 -> 28270.16 | T35: ='销售帐 MARTELUX'!M335+'销售帐 MARTELUX'!N335 -> 0 | U35: ='销售帐 MARTELUX'!$M446+'销售帐 MARTELUX'!$N446 -> 0 | V35: ='销售帐 MARTELUX'!$M610+'销售帐 MARTELUX'!$N610 -> 0 | W35: ='销售帐 MARTELUX'!$M839+'销售帐 MARTELUX'!$N839 -> 0 | X35: ='销售帐 MARTELUX'!$M1080+'销售帐 MARTELUX'!$N1080 -> 0 | Y35: ='销售帐 MARTELUX'!$M1351+'销售帐 MARTELUX'!$N1351 -> 0 | Z35: ='销售帐 MARTELUX'!$M1557+'销售帐 MARTELUX'!$N1557 -> 0 | AA35: ='销售帐 MARTELUX'!$M1742+'销售帐 MARTELUX'!$N1742 -> 0 | AB35: ='销售帐 MARTELUX'!$M1895+'销售帐 MARTELUX'!$N1895 -> 0 | AC35: ='销售帐 MARTELUX'!$M1929+'销售帐 MARTELUX'!$N1929 -> 0
A36: NORTE | B36: 诺基土 | C36: 主营业务收入 | D36: =SUM(E36:P36) -> 50406.74 | E36: =ROUND(R36*$R$3,2)+0.01 -> 49744.39 | F36: =ROUND(S36*$S$3,2) -> 662.35 | G36: =ROUND(T36*$T$3,2) -> 0 | H36: =ROUND(U36*$U$3,2) -> 0 | I36: =ROUND(V36*V$3,2) -> 0 | J36: =ROUND(W36*W$3,2) -> 0 | K36: =ROUND(X36*X$3,2) -> 0 | L36: =ROUND(Y36*Y$3,2) -> 0 | M36: =ROUND(Z36*Z$3,2) -> 0 | N36: =ROUND(AC36*AC$3,2) -> 0 | O36: =ROUND(AB36*AB$3,2) -> 0 | P36: =ROUND(AC36*AC$3,2) -> 0 | Q36: =SUM(R36:AC36) -> 44995.53 | R36: ='销售帐NORTE TOOLS'!L32 -> 38591.45 | S36: ='销售帐NORTE TOOLS'!L37 -> 500 | T36: ='销售帐NORTE TOOLS'!L70 -> 0 | U36: ='销售帐NORTE TOOLS'!L89 -> 0 | V36: ='销售帐NORTE TOOLS'!L102 -> 0 | W36: ='销售帐NORTE TOOLS'!L135 -> 0 | X36: ='销售帐NORTE TOOLS'!L178 -> 0 | Y36: ='销售帐NORTE TOOLS'!L235 -> 0 | Z36: ='销售帐NORTE TOOLS'!L257 -> 0 | AA36: ='[1]销售帐NORTE TOOLS'!$L10 -> 5904.08 | AB36: ='销售帐NORTE TOOLS'!L289 -> 0 | AC36: 0 | AD36: =S36+S37 -> 500 | AE36: =F36+F37 -> 662.35 | AF36: =Y36+Y37 -> 0
A37: NORTE | B37: 诺基土 | C37: 财务费用--刷卡费 | D37: =SUM(E37:P37) -> 165.71 | E37: =ROUND(R37*$R$3,2) -> 165.71 | F37: =ROUND(S37*$S$3,2) -> 0 | G37: =ROUND(T37*$T$3,2) -> 0 | H37: =ROUND(U37*$U$3,2) -> 0 | I37: =ROUND(V37*V$3,2) -> 0 | J37: =ROUND(W37*W$3,2) -> 0 | K37: =ROUND(X37*X$3,2) -> 0 | L37: =ROUND(Y37*Y$3,2) -> 0 | M37: =ROUND(Z37*Z$3,2) -> 0 | N37: =ROUND(AC37*AC$3,2) -> 0 | O37: =ROUND(AB37*AB$3,2) -> 0 | P37: =ROUND(AC37*AC$3,2) -> 0 | Q37: =SUM(R37:AC37) -> 204.48 | R37: ='销售帐NORTE TOOLS'!R32 -> 128.56 | S37: ='销售帐NORTE TOOLS'!R37 -> 0 | T37: ='销售帐NORTE TOOLS'!R70 -> 0 | U37: ='销售帐NORTE TOOLS'!R89 -> 0 | V37: ='销售帐NORTE TOOLS'!R102 -> 0 | W37: ='销售帐NORTE TOOLS'!R135 -> 0 | X37: ='销售帐NORTE TOOLS'!R178 -> 0 | Y37: ='销售帐NORTE TOOLS'!R235 -> 0 | Z37: ='销售帐NORTE TOOLS'!R257 -> 0 | AA37: ='[1]销售帐NORTE TOOLS'!$R10 -> 75.92 | AB37: ='销售帐NORTE TOOLS'!Q289 -> 0 | AC37: 0
A38: NORTE | B38: 诺基土 | C38: 博莱多收款 | D38: =SUM(E38:P38) -> 21165.38 | E38: =ROUND(R38*$R$3,2) -> 21165.38 | F38: =ROUND(S38*$S$3,2) -> 0 | G38: =ROUND(T38*$T$3,2) -> 0 | H38: =ROUND(U38*$U$3,2) -> 0 | I38: =ROUND(V38*V$3,2) -> 0 | J38: =ROUND(W38*W$3,2) -> 0 | K38: =ROUND(X38*X$3,2) -> 0 | L38: =ROUND(Y38*Y$3,2) -> 0 | M38: =ROUND(Z38*Z$3,2) -> 0 | N38: =ROUND(AC38*AC$3,2) -> 0 | O38: =ROUND(AB38*AB$3,2) -> 0 | P38: =ROUND(AC38*AC$3,2) -> 0 | Q38: =SUM(R38:AC38) -> 16420 | R38: ='销售帐NORTE TOOLS'!O32 -> 16420 | S38: ='销售帐NORTE TOOLS'!O37 -> 0 | T38: ='销售帐NORTE TOOLS'!O70 -> 0 | U38: ='销售帐NORTE TOOLS'!O89 -> 0 | V38: ='销售帐NORTE TOOLS'!O102 -> 0 | W38: ='销售帐NORTE TOOLS'!O135 -> 0 | X38: ='销售帐NORTE TOOLS'!O178 -> 0 | Y38: ='销售帐NORTE TOOLS'!O235 -> 0 | Z38: ='销售帐NORTE TOOLS'!O257 -> 0 | AA38: ='[1]销售帐NORTE TOOLS'!$O10 -> 0 | AB38: ='销售帐NORTE TOOLS'!O289 -> 0 | AC38: 0
A39: NORTE | B39: 诺基土 | C39: 刷卡收款 | D39: =SUM(E39:P39) -> 8083.5 | E39: =ROUND(R39*$R$3,2)+0.01 -> 8083.5 | F39: =ROUND(S39*$S$3,2) -> 0 | G39: =ROUND(T39*$T$3,2) -> 0 | H39: =ROUND(U39*$U$3,2) -> 0 | I39: =ROUND(V39*V$3,2) -> 0 | J39: =ROUND(W39*W$3,2) -> 0 | K39: =ROUND(X39*X$3,2) -> 0 | L39: =ROUND(Y39*Y$3,2) -> 0 | M39: =ROUND(Z39*Z$3,2) -> 0 | N39: =ROUND(AC39*AC$3,2) -> 0 | O39: =ROUND(AB39*AB$3,2) -> 0 | P39: =ROUND(AC39*AC$3,2) -> 0 | Q39: =SUM(R39:AC39) -> 9751.13 | R39: ='销售帐NORTE TOOLS'!P32 -> 6271.13 | S39: ='销售帐NORTE TOOLS'!P37 -> 0 | T39: ='销售帐NORTE TOOLS'!P70 -> 0 | U39: ='销售帐NORTE TOOLS'!P89 -> 0 | V39: ='销售帐NORTE TOOLS'!P102 -> 0 | W39: ='销售帐NORTE TOOLS'!P135 -> 0 | X39: ='销售帐NORTE TOOLS'!P178 -> 0 | Y39: ='销售帐NORTE TOOLS'!P235 -> 0 | Z39: ='销售帐NORTE TOOLS'!P257 -> 0 | AA39: ='[1]销售帐NORTE TOOLS'!$P10 -> 3480 | AB39: ='销售帐NORTE TOOLS'!P289 -> 0 | AC39: 0 | AD39: =S39-S37 -> 0 | AE39: =Y39-Y37 -> 0 | AF39: =R39-R37 -> 6142.57
A40: NORTE | B40: 诺基土 | C40: 现款-现金、银行存款 | D40: =SUM(E40:P40) -> 21323.57 | E40: =ROUND(R40*$R$3,2)-0.01 -> 20661.22 | F40: =ROUND(S40*$S$3,2) -> 662.35 | G40: =ROUND(T40*$T$3,2) -> 0 | H40: =ROUND(U40*$U$3,2) -> 0 | I40: =ROUND(V40*V$3,2) -> 0 | J40: =ROUND(W40*W$3,2) -> 0 | K40: =ROUND(X40*X$3,2) -> 0 | L40: =ROUND(Y40*Y$3,2) -> 0 | M40: =ROUND(Z40*Z$3,2) -> 0 | N40: =ROUND(AC40*AC$3,2) -> 0 | O40: =ROUND(AB40*AB$3,2) -> 0 | P40: =ROUND(AC40*AC$3,2) -> 0 | Q40: =SUM(R40:AC40) -> 19028.88 | R40: ='销售帐NORTE TOOLS'!M32+'销售帐NORTE TOOLS'!N32 -> 16028.88 | S40: ='销售帐NORTE TOOLS'!M37+'销售帐NORTE TOOLS'!N37 -> 500 | T40: ='销售帐NORTE TOOLS'!M70+'销售帐NORTE TOOLS'!N70 -> 0 | U40: ='销售帐NORTE TOOLS'!M89+'销售帐NORTE TOOLS'!N89 -> 0 | V40: ='销售帐NORTE TOOLS'!N102 -> 0 | W40: ='销售帐NORTE TOOLS'!N135 -> 0 | X40: ='销售帐NORTE TOOLS'!N178 -> 0 | Y40: ='销售帐NORTE TOOLS'!M235+'销售帐NORTE TOOLS'!N235 -> 0 | Z40: ='销售帐NORTE TOOLS'!M257+'销售帐NORTE TOOLS'!N257 -> 0 | AA40: ='[1]销售帐NORTE TOOLS'!$M10+'[1]销售帐NORTE TOOLS'!$N10 -> 2500 | AB40: ='销售帐NORTE TOOLS'!N289 -> 0 | AC40: 0
...

Sheet 销售帐 -ARGOTECH
A1: 2026年巴西销售发票总帐(ARGOTECH阿家达 )
A2: 阿家达 | D2: =L2+R2-M2-N2-O2-P2 -> -9.0221874e-10 | F2: =SUBTOTAL(9,F4:F4284) -> 2587 | H2: =SUBTOTAL(9,H4:H4284) -> 2190983.5 | J2: =SUBTOTAL(9,J4:J4284) -> 2194448.6 | K2: =SUBTOTAL(9,K4:K4284) -> 2587 | L2: =SUBTOTAL(9,L4:L4284) -> 2192159.6 | M2: =SUBTOTAL(9,M4:M4284) -> 4939 | N2: =SUBTOTAL(9,N4:N4284) -> 701289.33 | O2: =SUBTOTAL(9,O4:O4284) -> 1282973.4 | P2: =SUBTOTAL(9,P4:P4284) -> 205246.87 | R2: =SUBTOTAL(9,R4:R4284) -> 2289.03 | T2: =J2-L2-R2 -> 2.6147973e-10
A3: 发生日期 | B3: 销售单号 | C3: 编码 | D3: 商品型号 | E3: 客户单位 | F3: 数量 | G3: 单价 | H3: 金额 | I3: 税率 | J3: 含税金额 | K3: 数量 | L3: 总金额 | M3: 现金 | N3: 银行存款 | O3: BOLETO | P3: 刷卡/COM | Q3: 退货 DEVOLUÇÃO | R3: 卡费/Taxa de cartão de | S3: 卡率 | T3: 备注/OBSERVAÇÕES
A4: 46027 | B4: 2328/2111 | D4: 销售 | E4: Equipodonto Assistencia | K4: 1 | L4: =M4+P4+O4+N4-R4 -> 1135.75 | N4: 1135.75 | T4: 05/01/2026- Argotech | BC4: 2100002016547 | BD4: 550W
A5: 46027 | B5: 2328/2111 | C5: 2100002016998 | D5: =VLOOKUP(C5,$BC:$BD,2,0) -> 1500W-4 | E5: EQUIPODONTO ASSISTENCIA TECNICA ODONTOLOGICA LTDA | F5: 1 | G5: 1100 | H5: =F5*G5 -> 1100 | I5: 0.0325 | J5: =ROUND(H5+H5*I5,2) -> 1135.75 | L5: =M5+P5+O5+N5-R5 -> 0 | BC5: 2100002016608 | BD5: 1200W-2
A6: 46027 | B6: 2330/2112 | D6: 销售 | E6: WG Odonto Manutencao | H6: =F6*G6 -> 0 | J6: =ROUND((H6*I6+H6),2) -> 0 | K6: 1 | L6: =M6+P6+O6+N6-R6 -> 552.22 | N6: 552.22 | T6: 05/01/2026-Argotech | BC6: 2100002016622 | BD6: 1100*2-50L
A7: 46027 | B7: 2330/2112 | C7: 2100002017018 | D7: =VLOOKUP(C7,$BC:$BD,2,0) -> COMP 750W 220V | E7: WG ODONTO MANUTENCAO E ASSISTENCIA TECNICA LTDA | F7: 1 | G7: 534.84 | H7: =F7*G7 -> 534.84 | I7: 0.0325 | J7: =ROUND(H7+H7*I7,2) -> 552.22 | L7: =M7+P7+O7+N7-R7 -> 0 | BC7: 2100002016639 | BD7: 配件
A8: 46027 | B8: 2332/2113 | D8: 销售 | E8: Felipe Martiniano | H8: =F8*G8 -> 0 | J8: =ROUND(H8+H8*I8,2) -> 0 | K8: 1 | L8: =M8+P8+O8+N8-R8 -> 583 | N8: =484.5+98.5 -> 583 | T8: 05/01/2026-Argotech | BC8: 2100002016691 | BD8: 1200-8L
A9: 46027 | B9: 2332/2113 | C9: 2100002017001 | D9: =VLOOKUP(C9,$BC:$BD,2,0) -> COMP 550W 110V | E9: FELIPE MARTINIANO ASSUNCAO | F9: 1 | G9: 469.25 | H9: =F9*G9 -> 469.25 | I9: 0.0325 | J9: =ROUND(H9+H9*I9,2)+98.5 -> 583 | L9: =M9+P9+O9+N9-R9 -> 0 | BC9: 2100002016738 | BD9: 1100-25L
A10: 46027 | B10: 2335/2114 | D10: 销售 | E10: VRV Ferramentas | H10: =F10*G10 -> 0 | J10: =ROUND(H10+H10*I10,2) -> 0 | K10: 1 | L10: =M10+P10+O10+N10-R10 -> 645.33 | P10: 661 | R10: =ROUND(P10*S10,2) -> 15.67 | S10: 0.0237 | T10: 05/01/2026-Argotech | BC10: 2100002016745 | BD10: 1100*2 50L
A11: 46027 | B11: 2335/2114 | C11: 2100002017032 | D11: =VLOOKUP(C11,$BC:$BD,2,0) -> 1100 8L | E11: VRV FERRAMENTAS | F11: 1 | G11: 661 | H11: =F11*G11 -> 661 | J11: =ROUND(H11+H11*I11,2) -> 661 | L11: =M11+P11+O11+N11-R11 -> 0 | BC11: 2100002016752 | BD11: 1200 25L
A12: 46028 | B12: 2333/2115 | D12: 销售-内部 | E12: Norte Tools | H12: =F12*G12 -> 0 | J12: =ROUND(H12+H12*I12,2) -> 0 | T12: 07/04/2026-Argotech | BC12: 2100002016769 | BD12: 1100- 8L 127V
A13: 46028 | B13: 2337/2116 | D13: 销售 | E13: Odontek Equipamentos | H13: =F13*G13 -> 0 | J13: =ROUND(H13+H13*I13,2) -> 0 | K13: 9 | L13: =M13+P13+O13+N13-R13 -> 570 | N13: 570 | T13: 06/01/2026-Argotech | BC13: 2100002016790 | BD13: 1100 25L
A14: 46028 | B14: 2337/2116 | C14: 2100002017414 | D14: =VLOOKUP(C14,$BC:$BD,2,0) -> 配件 | E14: ODONTEK EQUIPAMENTOS ODONTOLOGICOS LTDA | F14: 1 | G14: 450 | H14: =F14*G14 -> 450 | J14: =ROUND(H14+H14*I14,2) -> 450 | L14: =M14+P14+O14+N14-R14 -> 0 | BC14: 2100002016837 | BD14: 1200*2-50L
A15: 46028 | B15: 2337/2116 | C15: 2100002016639 | D15: =VLOOKUP(C15,$BC:$BD,2,0) -> 配件 | E15: ODONTEK EQUIPAMENTOS ODONTOLOGICOS LTDA | F15: 8 | G15: 15 | H15: =F15*G15 -> 120 | J15: =ROUND(H15+H15*I15,2) -> 120 | L15: =M15+P15+O15+N15-R15 -> 0 | BC15: 2100002016875 | BD15: USK-750W
A16: 46028 | B16: 2329/2117 | D16: 销售 | E16: Ferragens Home | H16: =F16*G16 -> 0 | J16: =ROUND(H16+H16*I16,2) -> 0 | K16: 5 | L16: =M16+P16+O16+N16-R16 -> 4462.71 | P16: 4495.53 | R16: =ROUND(P16*S16,2) -> 32.82 | S16: 0.0073 | T16: 06/01/2026-Argotech | BC16: 2100002016899 | BD16: COMP-550W
A17: 46028 | B17: 2329/2117 | C17: 2100002017049 | D17: =VLOOKUP(C17,$BC:$BD,2,0) -> 1100*2 50L | E17: FERRAGENS HOME HOUSE COM. DE EQUIP. E MAQUINAS LTDA | F17: 1 | G17: 1524 | H17: =F17*G17 -> 1524 | J17: =ROUND(H17+H17*I17,2) -> 1524 | L17: =M17+P17+O17+N17-R17 -> 0 | BC17: 2100002016905 | BD17: COMP-750W
A18: 46028 | B18: 2329/2117 | C18: 2100002017469 | D18: =VLOOKUP(C18,$BC:$BD,2,0) -> BM-1902 25L 127V | E18: FERRAGENS HOME HOUSE COM. DE EQUIP. E MAQUINAS LTDA | F18: 1 | G18: 640 | H18: =F18*G18 -> 640 | J18: =ROUND(H18+H18*I18,2) -> 640 | L18: =M18+P18+O18+N18-R18 -> 0 | BC18: 2100002016912 | BD18: BM-1902-25L/127V
A19: 46028 | B19: 2329/2117 | C19: 2100002016776 | D19: =VLOOKUP(C19,$BC:$BD,2,0) -> 1200- 8L | E19: FERRAGENS HOME HOUSE COM. DE EQUIP. E MAQUINAS LTDA | F19: 2 | G19: 714.57 | H19: =F19*G19 -> 1429.14 | J19: =ROUND(H19+H19*I19,2) -> 1429.14 | L19: =M19+P19+O19+N19-R19 -> 0 | BC19: 2100002016967 | BD19: BM-1902-25L/127V
A20: 46028 | B20: 2329/2117 | C20: 2100002016752 | D20: =VLOOKUP(C20,$BC:$BD,2,0) -> 1200 25L | E20: FERRAGENS HOME HOUSE COM. DE EQUIP. E MAQUINAS LTDA | F20: 1 | G20: 902.39 | H20: =F20*G20 -> 902.39 | J20: =ROUND(H20+H20*I20,2) -> 902.39 | L20: =M20+P20+O20+N20-R20 -> 0 | BC20: 2100002016929 | BD20: BM-1902-25L
A21: 46028 | B21: 2336/2118 | D21: 取消 | E21: Clubemais Saude | H21: =F21*G21 -> 0 | J21: =ROUND(H21+H21*I21,2) -> 0 | L21: =M21+P21+O21+N21-R21 -> 0 | BC21: 2100002016974 | BD21: BM-1902-25L
A22: 46028 | B22: 2343/2119 | D22: 销售 | E22: Thiago Lourenço | H22: =F22*G22 -> 0 | J22: =ROUND(H22+H22*I22,2) -> 0 | K22: 2 | L22: =M22+P22+O22+N22-R22 -> 1206.4 | N22: 1206.4 | T22: 06/01/2026-Argotech | BC22: 2100002017124 | BD22: BM-1902-25L 220V
A23: 46028 | B23: 2343/2119 | C23: 2100002017018 | D23: =VLOOKUP(C23,$BC:$BD,2,0) -> COMP 750W 220V | E23: THIAGO LOURENCO DO AMARAL | F23: 2 | G23: 603.2 | H23: =F23*G23 -> 1206.4 | J23: =ROUND(H23+H23*I23,2) -> 1206.4 | L23: =M23+P23+O23+N23-R23 -> 0 | BC23: 2100002017131 | BD23: BM-1902 25L 127V
A24: 46028 | B24: 2344/2120 | D24: 销售 | E24: Jeferson Antonio | H24: =F24*G24 -> 0 | J24: =ROUND(H24+H24*I24,2) -> 0 | K24: 1 | L24: =M24+P24+O24+N24-R24 -> 390.52 | P24: 400 | R24: =ROUND(P24*S24,2) -> 9.48 | S24: 0.0237 | T24: 06/01/2026-Argotech | BC24: 2100002017193 | BD24: BM-1902-25L 220V
A25: 46028 | B25: 2344/2120 | C25: 2100002017414 | D25: =VLOOKUP(C25,$BC:$BD,2,0) -> 配件 | E25: JEFERSON ANTONIO PEREIRA ----1100 -220 V | F25: 1 | G25: 400 | H25: =F25*G25 -> 400 | J25: =ROUND(H25+H25*I25,2) -> 400 | L25: =M25+P25+O25+N25-R25 -> 0 | BC25: 2100002017285 | BD25: BM-1902 25L 127V
A26: 46027 | B26: 2334/2121 | D26: 销售 | E26: Protec Comercio | H26: =F26*G26 -> 0 | J26: =ROUND(H26+H26*I26,2) -> 0 | K26: 7 | L26: =M26+P26+O26+N26-R26 -> 4736.39 | N26: 4736.39 | T26: 06/01/2026-Argotech | BC26: 2100002017247 | BD26: BM-1902-25L 220V
A27: 46028 | B27: 2334/2121 | C27: 2100002016615 | D27: =VLOOKUP(C27,$BC:$BD,2,0) -> 1500W-2 | E27: PROTEC COMERCIO E MANUTENCAO DE EQUIPAMENTOS DE SAUDE LTDA | F27: 6 | G27: 639 | H27: =F27*G27 -> 3834 | J27: =ROUND(H27+H27*I27,2) -> 3834 | L27: =M27+P27+O27+N27-R27 -> 0 | BC27: 2100002017469 | BD27: BM-1902 25L 127V
A28: 46028 | B28: 2334/2121 | C28: 2100002016752 | D28: =VLOOKUP(C28,$BC:$BD,2,0) -> 1200 25L | E28: PROTEC COMERCIO E MANUTENCAO DE EQUIPAMENTOS DE SAUDE LTDA | F28: 1 | G28: 902.39 | H28: =F28*G28 -> 902.39 | J28: =ROUND(H28+H28*I28,2) -> 902.39 | L28: =M28+P28+O28+N28-R28 -> 0 | BC28: 2100002017292 | BD28: BM-1902 25L
A29: 46028 | B29: 2342/2122 | D29: 销售 | E29: WG Odonto Manutencao | H29: =F29*G29 -> 0 | J29: =ROUND(H29+H29*I29,2) -> 0 | K29: 1 | L29: =M29+P29+O29+N29-R29 -> 552.22 | N29: 552.22 | T29: 06/01/2026-Argotech | BC29: 2100002017520 | BD29: BM-1902-25L 220V E
A30: 46028 | B30: 2342/2122 | C30: 2100002017018 | D30: =VLOOKUP(C30,$BC:$BD,2,0) -> COMP 750W 220V | E30: WG ODONTO MANUTENCAO E ASSISTENCIA TECNICA LTDA | F30: 1 | G30: 534.84 | H30: =F30*G30 -> 534.84 | I30: 0.0325 | J30: =ROUND(H30+H30*I30,2) -> 552.22 | L30: =M30+P30+O30+N30-R30 -> 0 | BC30: 2100002017544 | BD30: BM-1902-50L 220V E
A31: 46029 | B31: 2345/2123 | D31: 销售 | E31: PALACIO DAS FERRAMENTAS | H31: =F31*G31 -> 0 | J31: =ROUND(H31+H31*I31,2) -> 0 | K31: 20 | L31: =M31+P31+O31+N31-R31 -> 13180 | O31: 13180 | T31: 06/02/2026-Argotech | BC31: 2100002017568 | BD31: BM-1902-50L 127V E
A32: 46029 | B32: 2345/2123 | C32: 2100002017032 | D32: =VLOOKUP(C32,$BC:$BD,2,0) -> 1100 8L | E32: PALACIO DAS FERRAMENTAS E PARAFUSOS LTDA | F32: 20 | G32: 659 | H32: =F32*G32 -> 13180 | J32: =ROUND(H32+H32*I32,2) -> 13180 | L32: =M32+P32+O32+N32-R32 -> 0 | BC32: 2100002017537 | BD32: BM-1902-50L 127V E
A33: 46029 | B33: 2347/2124 | D33: 销售 | E33: Ferragens Home | H33: =F33*G33 -> 0 | J33: =ROUND(H33+H33*I33,2) -> 0 | K33: 6 | L33: =M33+P33+O33+N33-R33 -> 4256.12 | P33: 4287.42 | R33: =ROUND(P33*S33,2) -> 31.3 | S33: 0.0073 | T33: 07/01/2026-Argotech | BC33: 2100002016981 | BD33: 1500-50L
A34: 46029 | B34: 2347/2124 | C34: 2100002016776 | D34: =VLOOKUP(C34,$BC:$BD,2,0) -> 1200- 8L | E34: FERRAGENS HOME HOUSE COM. DE EQUIP. E MAQUINAS LTDA | F34: 6 | G34: 714.57 | H34: =F34*G34 -> 4287.42 | J34: =ROUND(H34+H34*I34,2) -> 4287.42 | L34: =M34+P34+O34+N34-R34 -> 0 | BC34: 2100002017414 | BD34: 配件
A35: 46029 | B35: 2350/2125 | D35: 销售 | E35: francisco Norberto | H35: =F35*G35 -> 0 | J35: =ROUND(H35+H35*I35,2) -> 0 | K35: 1 | L35: =M35+P35+O35+N35-R35 -> 1050.28 | P35: 1058 | R35: =ROUND(P35*S35,2) -> 7.72 | S35: 0.0073 | T35: 07/01/2026-Argotech | BC35: 2100002017490 | BD35: 1500W-4
A36: 46029 | B36: 2350/2125 | C36: 2100002017490 | D36: =VLOOKUP(C36,$BC:$BD,2,0) -> 1500W-4 | E36: FRANCISCO NORBERTO DA SILVA | F36: 1 | G36: 1058 | H36: =F36*G36 -> 1058 | J36: =ROUND(H36+H36*I36,2) -> 1058 | L36: =M36+P36+O36+N36-R36 -> 0 | BC36: 6973858620017 | BD36: 550-8L
A37: 46028 | B37: 2341/2126 | D37: 销售 | E37: Assistecdonto LTDA | H37: =F37*G37 -> 0 | J37: =ROUND(H37+H37*I37,2) -> 0 | K37: 22 | L37: =M37+P37+O37+N37-R37 -> 5354.93 | N37: 5354.93 | T37: 07/01/2026-Argotech | BC37: 2100002017810 | BD37: 550-8L
A38: 46029 | B38: 2341/2126 | C38: 2100002017148 | D38: =VLOOKUP(C38,$BC:$BD,2,0) -> 1500W-4 | E38: ASSISTECDONTO LTDA | F38: 2 | G38: 1058 | H38: =F38*G38 -> 2116 | I38: 0.0325 | J38: =ROUND(H38+H38*I38,2) -> 2184.77 | L38: =M38+P38+O38+N38-R38 -> 0 | BC38: 2100002017803 | BD38: 750-25L
A39: 46029 | B39: 2341/2126 | C39: 2100002016875 | D39: =VLOOKUP(C39,$BC:$BD,2,0) -> USK-750W | E39: ASSISTECDONTO LTDA | F39: 4 | G39: 632 | H39: =F39*G39 -> 2528 | I39: 0.0325 | J39: =ROUND(H39+H39*I39,2) -> 2610.16 | L39: =M39+P39+O39+N39-R39 -> 0 | BC39: 6973858620084 | BD39: 750-25L
A40: 46029 | B40: 2341/2126 | C40: 2100002017216 | D40: 配件 | E40: ASSISTECDONTO LTDA | F40: 10 | G40: 20 | H40: =F40*G40 -> 200 | J40: =ROUND(H40+H40*I40,2) -> 200 | L40: =M40+P40+O40+N40-R40 -> 0 | BC40: 2100002017483 | BD40: 750-25L
...

Sheet 销售帐CAIYA
A1: 2026年巴西销售发票总帐(CAIYA )
A2: 界野 | D2: =L2+R2-M2-N2-O2-P2 -> -5.0022209e-12 | F2: =SUBTOTAL(9,F4:F721) -> 223 | H2: =SUBTOTAL(9,H4:H721) -> 44886.94 | J2: =SUBTOTAL(9,J4:J721) -> 44886.48 | K2: =SUBTOTAL(9,K4:K721) -> 220 | L2: =SUBTOTAL(9,L4:L721) -> 44823.47 | M2: =SUBTOTAL(9,M4:M721) -> 0 | N2: =SUBTOTAL(9,N4:N721) -> 17533.3 | O2: =SUBTOTAL(9,O4:O721) -> 24694.58 | P2: =SUBTOTAL(9,P4:P721) -> 2658.6 | Q2: =SUBTOTAL(9,Q4:Q721) -> 0 | R2: =J2-L2-Q2 -> 63.01
A3: 发生日期 | B3: 销售单号 | C3: 编码 | D3: 商品型号 | E3: 客户单位 | F3: 数量 | G3: 单价 | H3: 金额 | I3: 税率 | J3: 含税金额 | K3: 数量 | L3: 总金额 | M3: 现金 | N3: 银行存款 | O3: BOLETO | P3: 刷卡/cartão | Q3: 退货 DEVOLUÇÃO | R3: 手续费/comissão | S3: 卡率 | T3: 备注/OBSERVAÇÕES
A4: 46027 | B4: 4198/3630 | D4: 销售-内部 | E4: Norte Tools | L4: =M4+P4+O4+N4-Q4 -> 0 | T4: 07/04/2026-Caiya | BC4: 8424608028624 | BD4: US/MMA 280 BIVOLT
A5: 46027 | B5: 4201/3631 | D5: 销售 | E5: Nova Parafer | H5: =F5*G5 -> 0 | J5: =ROUND((H5*I5+H5),2) -> 0 | L5: =M5+P5+O5+N5-Q5 -> 1598.7 | O5: 1598.7 | T5: 06/02/2026,08/03/2026 e 07/04/2026-CAIYA | BC5: 8002126321436 | BD5: MINI MMA-190
A6: 46029 | B6: 4201/3631 | C6: 8424608028624 | D6: =VLOOKUP(C6,$BC:$BD,2,0) -> US/MMA 280 BIVOLT | E6: NOVA PARAFER-COMERCIO DE FERRAGENS LTDA - EPP | F6: 3 | G6: 532.9 | H6: =F6*G6 -> 1598.7 | J6: =ROUND(H6+H6*I6,2) -> 1598.7 | L6: =M6+P6+O6+N6-Q6 -> 0 | BC6: 8424608028419 | BD6: BC-430
A7: 46027 | B7: 4199/3632 | D7: 销售 | E7: lojao Das Ferramentas | H7: =F7*G7 -> 0 | J7: =ROUND(H7+H7*I7,2) -> 0 | K7: 14 | L7: =M7+P7+O7+N7-Q7 -> 2658.46 | N7: 2658.46 | R7: 0 | T7: 06/01/2026-Caiya
A8: 46030 | B8: 4199/3632 | C8: 8002126321436 | D8: =VLOOKUP(C8,$BC:$BD,2,0) -> MINI MMA-190 | E8: LOJAO DAS FERRAMENTAS LTDA | F8: 14 | G8: 189.89 | H8: =F8*G8 -> 2658.46 | J8: =ROUND(H8+H8*I8,2) -> 2658.46 | L8: =M8+P8+O8+N8-Q8 -> 0
A9: 46027 | B9: 4200/3633 | D9: 销售 | E9: Silva Ferragens | H9: =F9*G9 -> 0 | J9: =ROUND(H9+H9*I9,2) -> 0 | K9: 14 | L9: =M9+P9+O9+N9-Q9 -> 2658.46 | O9: 2658.46 | R9: 0 | T9: 08/02/2026, 08/03/2026 e 08/04/2026-Caiya
A10: 46030 | B10: 4200/3633 | C10: 8002126321436 | D10: =VLOOKUP(C10,$BC:$BD,2,0) -> MINI MMA-190 | E10: SILVA FERRAGENS LTDA | F10: 14 | G10: 189.89 | H10: =F10*G10 -> 2658.46 | J10: =ROUND(H10+H10*I10,2) -> 2658.46 | L10: =M10+P10+O10+N10-Q10 -> 0
A11: 46027 | B11: 4202/3634 | D11: 销售 | E11: Garavelo Parafusos | H11: =F11*G11 -> 0 | J11: =ROUND(H11+H11*I11,2) -> 0 | K11: 14 | L11: =M11+P11+O11+N11-Q11 -> 2658.46 | O11: 2658.46 | R11: 0 | T11: 14/02/2026,16/03/2026 e 14/04/2026
A12: 46035 | B12: 4202/3634 | C12: 8002126321436 | D12: =VLOOKUP(C12,$BC:$BD,2,0) -> MINI MMA-190 | E12: GARAVELO PARAFUSOS LTDA | F12: 14 | G12: 189.89 | H12: =F12*G12 -> 2658.46 | J12: =ROUND(H12+H12*I12,2) -> 2658.46 | L12: =M12+P12+O12+N12-Q12 -> 0
A13: 46027 | B13: 4203/3635 | D13: 销售 | E13: R C Nepomuceno | H13: =F13*G13 -> 0 | J13: =ROUND(H13+H13*I13,2) -> 0 | K13: 14 | L13: =M13+P13+O13+N13-Q13 -> 2658.46 | N13: 2658.46 | R13: 0 | T13: 13/01/2026- Caiya
A14: 46035 | B14: 4203/3635 | C14: 8002126321436 | D14: =VLOOKUP(C14,$BC:$BD,2,0) -> MINI MMA-190 | E14: R C NEPOMUCENO DE FERRAMENTAS | F14: 14 | G14: 189.89 | H14: =F14*G14 -> 2658.46 | J14: =ROUND(H14+H14*I14,2) -> 2658.46 | L14: =M14+P14+O14+N14-Q14 -> 0
A15: 46027 | B15: 4204/3636 | D15: 销售-内部 | E15: Norte Tools | H15: =F15*G15 -> 0 | J15: =ROUND(H15+H15*I15,2) -> 0 | L15: =M15+P15+O15+N15-Q15 -> 0 | R15: 0 | T15: 20/04/2026-Caiya
A16: 46042 | B16: 4205/3637 | D16: 销售 | E16: Industria e Comercio | H16: =F16*G16 -> 0 | J16: =ROUND(H16+H16*I16,2) -> 0 | K16: 4 | L16: =M16+P16+O16+N16-Q16 -> 1195.64 | O16: 1195.64 | R16: 0 | T16: 23/02/2026-CAIYA
A17: 46045 | B17: 4205/3637 | C17: 8002126321436 | D17: =VLOOKUP(C17,$BC:$BD,2,0) -> MINI MMA-190 | E17: INDUSTRIA E COMERCIO DE BOMBAS VERISSIMO LTDA | F17: 4 | G17: 298.91 | H17: =F17*G17 -> 1195.64 | J17: =ROUND(H17+H17*I17,2) -> 1195.64 | L17: =M17+P17+O17+N17-Q17 -> 0
A18: 46048 | B18: 4206/3638 | D18: 销售-内部 | E18: Norte Tools | H18: =F18*G18 -> 0 | J18: =ROUND(H18+H18*I18,2) -> 0 | L18: =M18+P18+O18+N18-Q18 -> 0 | R18: 0 | T18: 29/03/2026-CAIYA
A19: 46049 | B19: /3639 | D19: 运输 发票 | E19: REMESSA | H19: =F19*G19 -> 0 | J19: =ROUND(H19+H19*I19,2) -> 0 | L19: =M19+P19+O19+N19-Q19 -> 0 | R19: 0
A20: 46050 | B20: /3640 | D20: 运输 发票 | E20: REMESSA | H20: =F20*G20 -> 0 | J20: =ROUND(H20+H20*I20,2) -> 0 | L20: =M20+P20+O20+N20-Q20 -> 0 | R20: 0
A21: 46052 | B21: 4208/3641 | D21: 销售 | E21: Fabio Souza | H21: =F21*G21 -> 0 | J21: =ROUND(H21+H21*I21,2) -> 0 | K21: 14 | L21: =M21+P21+O21+N21-Q21 -> 2658 | N21: 2658 | R21: 0 | T21: 30/01/2026-CAIYA
A22: 46052 | B22: 4208/3641 | C22: 8002126321436 | D22: =VLOOKUP(C22,$BC:$BD,2,0) -> MINI MMA-190 | E22: FABIO SOUZA DE JESUS | F22: 14 | G22: 189.89 | H22: =F22*G22 -> 2658.46 | J22: =ROUND(H22+H22*I22,2)-0.46 -> 2658 | L22: =M22+P22+O22+N22-Q22 -> 0
A23: 46053 | B23: 本月合计 | F23: =SUBTOTAL(9,F4:F22) -> 77 | H23: =SUBTOTAL(9,H4:H22) -> 16086.64 | J23: =SUBTOTAL(9,J4:J22) -> 16086.18 | K23: =SUBTOTAL(9,K4:K22) -> 74 | L23: =SUBTOTAL(9,L4:L22) -> 16086.18 | M23: =SUBTOTAL(9,M4:M22) -> 0 | N23: =SUBTOTAL(9,N4:N22) -> 7974.92 | O23: =SUBTOTAL(9,O4:O22) -> 8111.26 | P23: =SUBTOTAL(9,P4:P22) -> 0 | Q23: =SUBTOTAL(9,Q4:Q22) -> 0 | R23: =ROUND(J23-L23-Q23,2) -> 0 | T23: =J23-L23-R23 -> 0
A24: 46062 | B24: 4207/3642 | D24: 销售 | E24: Batista e silva | H24: =F24*G24 -> 0 | J24: =ROUND(H24+H24*I24,2) -> 0 | K24: 14 | L24: =SUM(M24+N24+O24+P24-Q24-R24) -> 2659.86 | O24: 2659.86 | T24: 10/03/2026, 10/04/2026 e 10/05/2026-CAIYA
A25: 46062 | B25: 4207/3642 | C25: 8002126321436 | D25: =VLOOKUP(C25,$BC:$BD,2,0) -> MINI MMA-190 | E25: BATISTA E SILVA COMERCIO DE FERRAGENS E MATERIAIS | F25: 14 | G25: 189.99 | H25: =F25*G25 -> 2659.86 | J25: =ROUND(H25+H25*I25,2) -> 2659.86 | L25: =SUM(M25+N25+O25+P25-Q25-R25) -> 0
A26: 46063 | B26: 4209/3643 | D26: 销售 | E26: VL Ferramentas | H26: =F26*G26 -> 0 | J26: =ROUND(H26+H26*I26,2) -> 0 | K26: 14 | L26: =SUM(M26+N26+O26+P26-Q26-R26) -> 2595.59 | P26: 2658.6 | R26: =ROUND(P26*S26,2) -> 63.01 | S26: 0.0237 | T26: 06/02/2026-CAIYA
A27: 46063 | B27: 4209/3643 | C27: 8002126321436 | D27: =VLOOKUP(C27,$BC:$BD,2,0) -> MINI MMA-190 | E27: VL FERRAMENTAS EIRELI - ME | F27: 14 | G27: 189.9 | H27: =F27*G27 -> 2658.6 | J27: =ROUND(H27+H27*I27,2) -> 2658.6 | L27: =SUM(M27+N27+O27+P27-Q27-R27) -> 0
A28: 46064 | B28: 4210/3644 | D28: 销售 | E28: J C Nepomuceno | H28: =F28*G28 -> 0 | J28: =ROUND(H28+H28*I28,2) -> 0 | K28: 16 | L28: =SUM(M28+N28+O28+P28-Q28-R28) -> 3038.24 | N28: 3038.24 | R28: =P28*S28 -> 0 | T28: 11/02/2026-CAIYA
